Workbook

Sheet How to use
A1: INFORM Tanzania - Data Collection Tool (NORMAL / v1)
A3: 1. Filter the "Sector" column on the Data Entry sheet to find YOUR indicators.
A4: 2. For each, type the ACTUAL VALUE in its own unit (e.g. 18 for 18% underweight, 11 for an
A5: 11-year drought frequency, a count of displaced people). The unit is shown on each row.
A6: 3. The "0-10 (auto)" column standardises it instantly - exactly as the official INFORM workbook.
A7: You never invent a score; the tool computes it. These cells are locked.
A8: 4. Leave rows you do not have data for BLANK - the model uses the foundation value, nothing breaks.
A9: 5. Save and send the file back. The centre reads only the 0-10 values; your raw stays with you.
A11: Reference = the fixed Min/Max the value is scaled against (frozen, so a value means the same at
A12: district, region, country, or village). Direction "protective" means higher is better (inverted).
A13: Only the ACTUAL VALUE column is editable. The ADVANCED version adds research rows (SPEI, soil
A14: moisture, water levels...) for sectors to refine an indicator beyond the legacy single source.

Sheet Data Entry
A1: Sector | B1: Dimension | C1: Component | D1: Indicator | E1: Unit | F1: Level | G1: Transform | H1: Ref Min | I1: Ref Max | J1: Direction | K1: ACTUAL VALUE | L1: 0-10 (auto)
A2: PMO-DMD | B2: Hazards & Exposure | C2: Human / Conflict Intensity | D2: Conflict Barometer | E2: Index | F2: Adm1 | G2: None | H2: 0 | I2: 5 | J2: risk | L2: =IF(K2="","",IFERROR(MAX(0,MIN(10,ROUND(IF(J2="protective",10-10*((IF(G2="Logarithm",LN(0.001+K2),IF(G2="Exponential",EXP(K2),K2)))-H2)/(I2-H2),10*((IF(G2="Logarithm",LN(0.001+K2),IF(G2="Exponential",EXP(K2),K2)))-H2)/(I2-H2)),1))),"No data"))
A3: PMO-DMD | B3: Hazards & Exposure | C3: Human / Conflict Risk | D3: GCRI derived Conflict probability | E3: % | F3: National | G3: None | H3: 0 | I3: 99.1 | J3: risk | L3: =IF(K3="","",IFERROR(MAX(0,MIN(10,ROUND(IF(J3="protective",10-10*((IF(G3="Logarithm",LN(0.001+K3),IF(G3="Exponential",EXP(K3),K3)))-H3)/(I3-H3),10*((IF(G3="Logarithm",LN(0.001+K3),IF(G3="Exponential",EXP(K3),K3)))-H3)/(I3-H3)),1))),"No data"))
A4: TPF/PMO-DMD | B4: Hazards & Exposure | C4: Human / Internal Violence | D4: Number of Events | E4: Number | F4: Adm1 | G4: Logarithm | H4: 0.00099950033 | I4: 4.0430688 | J4: risk | L4: =IF(K4="","",IFERROR(MAX(0,MIN(10,ROUND(IF(J4="protective",10-10*((IF(G4="Logarithm",LN(0.001+K4),IF(G4="Exponential",EXP(K4),K4)))-H4)/(I4-H4),10*((IF(G4="Logarithm",LN(0.001+K4),IF(G4="Exponential",EXP(K4),K4)))-H4)/(I4-H4)),1))),"No data"))
A5: TPF/PMO-DMD | B5: Hazards & Exposure | C5: Human / Internal Violence | D5: Number of Fatalities | E5: Number | F5: Adm1 | G5: Logarithm | H5: -6.9077553 | I5: 3.8918407 | J5: risk | L5: =IF(K5="","",IFERROR(MAX(0,MIN(10,ROUND(IF(J5="protective",10-10*((IF(G5="Logarithm",LN(0.001+K5),IF(G5="Exponential",EXP(K5),K5)))-H5)/(I5-H5),10*((IF(G5="Logarithm",LN(0.001+K5),IF(G5="Exponential",EXP(K5),K5)))-H5)/(I5-H5)),1))),"No data"))
A6: TMA | B6: Hazards & Exposure | C6: Natural / Coastal hazards | D6: Coastal Erosion | E6: meters / year | F6: Adm2 | G6: None | H6: -0.3 | I6: 0 | J6: protective | L6: =IF(K6="","",IFERROR(MAX(0,MIN(10,ROUND(IF(J6="protective",10-10*((IF(G6="Logarithm",LN(0.001+K6),IF(G6="Exponential",EXP(K6),K6)))-H6)/(I6-H6),10*((IF(G6="Logarithm",LN(0.001+K6),IF(G6="Exponential",EXP(K6),K6)))-H6)/(I6-H6)),1))),"No data"))
A7: TMA | B7: Hazards & Exposure | C7: Natural / Drought | D7: Historic Drought Frequency | E7: years | F7: Adm1 | G7: None | H7: 5 | I7: 19 | J7: risk | L7: =IF(K7="","",IFERROR(MAX(0,MIN(10,ROUND(IF(J7="protective",10-10*((IF(G7="Logarithm",LN(0.001+K7),IF(G7="Exponential",EXP(K7),K7)))-H7)/(I7-H7),10*((IF(G7="Logarithm",LN(0.001+K7),IF(G7="Exponential",EXP(K7),K7)))-H7)/(I7-H7)),1))),"No data"))
A8: TMA/GST | B8: Hazards & Exposure | C8: Natural / Earthquake | D8: Earthquake exposure | E8: index | F8: Adm2 | G8: None | H8: 0 | I8: 1.0000001 | J8: risk | L8: =IF(K8="","",IFERROR(MAX(0,MIN(10,ROUND(IF(J8="protective",10-10*((IF(G8="Logarithm",LN(0.001+K8),IF(G8="Exponential",EXP(K8),K8)))-H8)/(I8-H8),10*((IF(G8="Logarithm",LN(0.001+K8),IF(G8="Exponential",EXP(K8),K8)))-H8)/(I8-H8)),1))),"No data"))
A9: NEMC | B9: Hazards & Exposure | C9: Natural / Environmental Degradation | D9: Deforestation - Treecover Loss | E9: % | F9: Adm2 | G9: Logarithm | H9: -6.9077553 | I9: -1.0023578 | J9: risk | L9: =IF(K9="","",IFERROR(MAX(0,MIN(10,ROUND(IF(J9="protective",10-10*((IF(G9="Logarithm",LN(0.001+K9),IF(G9="Exponential",EXP(K9),K9)))-H9)/(I9-H9),10*((IF(G9="Logarithm",LN(0.001+K9),IF(G9="Exponential",EXP(K9),K9)))-H9)/(I9-H9)),1))),"No data"))
A10: NEMC | B10: Hazards & Exposure | C10: Natural / Environmental Degradation | D10: Soil Erosion | E10: Mg/ha/yr | F10: National | G10: None | H10: 1.7 | I10: 15.9 | J10: risk | L10: =IF(K10="","",IFERROR(MAX(0,MIN(10,ROUND(IF(J10="protective",10-10*((IF(G10="Logarithm",LN(0.001+K10),IF(G10="Exponential",EXP(K10),K10)))-H10)/(I10-H10),10*((IF(G10="Logarithm",LN(0.001+K10),IF(G10="Exponential",EXP(K10),K10)))-H10)/(I10-H10)),1))),"No data"))
A11: PMO-DMD | B11: Hazards & Exposure | C11: Natural / Flood | D11: Flood exposure | E11: % | F11: Adm2 | G11: Logarithm | H11: -6.9077553 | I11: -1.1488535 | J11: risk | L11: =IF(K11="","",IFERROR(MAX(0,MIN(10,ROUND(IF(J11="protective",10-10*((IF(G11="Logarithm",LN(0.001+K11),IF(G11="Exponential",EXP(K11),K11)))-H11)/(I11-H11),10*((IF(G11="Logarithm",LN(0.001+K11),IF(G11="Exponential",EXP(K11),K11)))-H11)/(I11-H11)),1))),"No data"))
A12: TMA | B12: Hazards & Exposure | C12: Natural / Landslide | D12: Landslide exposure | E12: % | F12: Adm2 | G12: Logarithm | H12: -6.9077553 | I12: 0.00099950033 | J12: risk | L12: =IF(K12="","",IFERROR(MAX(0,MIN(10,ROUND(IF(J12="protective",10-10*((IF(G12="Logarithm",LN(0.001+K12),IF(G12="Exponential",EXP(K12),K12)))-H12)/(I12-H12),10*((IF(G12="Logarithm",LN(0.001+K12),IF(G12="Exponential",EXP(K12),K12)))-H12)/(I12-H12)),1))),"No data"))
A13: TMA | B13: Hazards & Exposure | C13: Natural / Storms & Cyclone | D13: Cyclone exposure - max speed | E13: % | F13: Adm2 | G13: None | H13: 0 | I13: 18.10675 | J13: risk | L13: =IF(K13="","",IFERROR(MAX(0,MIN(10,ROUND(IF(J13="protective",10-10*((IF(G13="Logarithm",LN(0.001+K13),IF(G13="Exponential",EXP(K13),K13)))-H13)/(I13-H13),10*((IF(G13="Logarithm",LN(0.001+K13),IF(G13="Exponential",EXP(K13),K13)))-H13)/(I13-H13)),1))),"No data"))
... A22: NBS/MoFP | B22: Vulnerability | C22: Socio-Economics / Economic Dependency | D22: Net ODA received (% of GNI) | E22: % | F22: National | G22: None | H22: 0.2 | I22: 14.5 | J22: risk | L22: =IF(K22="","",IFERROR(MAX(0,MIN(10,ROUND(IF(J22="protective",10-10*((IF(G22="Logarithm",LN(0.001+K22),IF(G22="Exponential",EXP(K22),K22)))-H22)/(I22-H22),10*((IF(G22="Logarithm",LN(0.001+K22),IF(G22="Exponential",EXP(K22),K22)))-H22)/(I22-H22)),1))),"No data"))
A23: NBS/MoFP | B23: Vulnerability | C23: Socio-Economics / Economic Dependency | D23: Personal remittances | E23: % | F23: National | G23: None | H23: 0 | I23: 6.4 | J23: risk | L23: =IF(K23="","",IFERROR(MAX(0,MIN(10,ROUND(IF(J23="protective",10-10*((IF(G23="Logarithm",LN(0.001+MAX(MIN(K23,0.67),0.67)),IF(G23="Exponential",EXP(MAX(MIN(K23,0.67),0.67)),MAX(MIN(K23,0.67),0.67))))-H23)/(I23-H23),10*((IF(G23="Logarithm",LN(0.001+MAX(MIN(K23,0.67),0.67)),IF(G23="Exponential",EXP(MAX(MIN(K23,0.67),0.67)),MAX(MIN(K23,0.67),0.67))))-H23)/(I23-H23)),1))),"No data"))
A24: NBS | B24: Vulnerability | C24: Socio-Economics / Habitat | D24: Population in informal settlements | E24: % | F24: National | G24: None | H24: 17 | I24: 78.4 | J24: risk | L24: =IF(K24="","",IFERROR(MAX(0,MIN(10,ROUND(IF(J24="protective",10-10*((IF(G24="Logarithm",LN(0.001+K24),IF(G24="Exponential",EXP(K24),K24)))-H24)/(I24-H24),10*((IF(G24="Logarithm",LN(0.001+K24),IF(G24="Exponential",EXP(K24),K24)))-H24)/(I24-H24)),1))),"No data"))
A25: NBS | B25: Vulnerability | C25: Socio-Economics / Habitat | D25: Urban Population | E25: % | F25: Adm1 | G25: None | H25: 6.3 | I25: 100 | J25: risk | L25: =IF(K25="","",IFERROR(MAX(0,MIN(10,ROUND(IF(J25="protective",10-10*((IF(G25="Logarithm",LN(0.001+K25),IF(G25="Exponential",EXP(K25),K25)))-H25)/(I25-H25),10*((IF(G25="Logarithm",LN(0.001+K25),IF(G25="Exponential",EXP(K25),K25)))-H25)/(I25-H25)),1))),"No data"))
A26: MUCHALI/IPC | B26: Vulnerability | C26: Socio-Economics / Livelihoods | D26: Food Security - Insufficient food | E26: % pop phase 2 or higher | F26: Adm1 | G26: None | H26: 0 | I26: 149 | J26: risk | L26: =IF(K26="","",IFERROR(MAX(0,MIN(10,ROUND(IF(J26="protective",10-10*((IF(G26="Logarithm",LN(0.001+K26),IF(G26="Exponential",EXP(K26),K26)))-H26)/(I26-H26),10*((IF(G26="Logarithm",LN(0.001+K26),IF(G26="Exponential",EXP(K26),K26)))-H26)/(I26-H26)),1))),"No data"))
A27: MoH/TFNC | B27: Vulnerability | C27: Vulnerable Groups / Children Health and Nutrition | D27: Child mortality | E27: per 1,000 live births | F27: Adm1 | G27: None | H27: 3.68 | I27: 42.48 | J27: risk | L27: =IF(K27="","",IFERROR(MAX(0,MIN(10,ROUND(IF(J27="protective",10-10*((IF(G27="Logarithm",LN(0.001+K27),IF(G27="Exponential",EXP(K27),K27)))-H27)/(I27-H27),10*((IF(G27="Logarithm",LN(0.001+K27),IF(G27="Exponential",EXP(K27),K27)))-H27)/(I27-H27)),1))),"No data"))
A28: MoH/TFNC | B28: Vulnerability | C28: Vulnerable Groups / Children Health and Nutrition | D28: Children Underweight | E28: % | F28: Adm1 | G28: None | H28: 6.2 | I28: 20 | J28: risk | L28: =IF(K28="","",IFERROR(MAX(0,MIN(10,ROUND(IF(J28="protective",10-10*((IF(G28="Logarithm",LN(0.001+K28),IF(G28="Exponential",EXP(K28),K28)))-H28)/(I28-H28),10*((IF(G28="Logarithm",LN(0.001+K28),IF(G28="Exponential",EXP(K28),K28)))-H28)/(I28-H28)),1))),"No data"))
A29: MoH/TFNC | B29: Vulnerability | C29: Vulnerable Groups / Children Health and Nutrition | D29: Infant mortality | E29: per 1,000 live births | F29: Adm1 | G29: None | H29: 28.27 | I29: 76.57 | J29: risk | L29: =IF(K29="","",IFERROR(MAX(0,MIN(10,ROUND(IF(J29="protective",10-10*((IF(G29="Logarithm",LN(0.001+K29),IF(G29="Exponential",EXP(K29),K29)))-H29)/(I29-H29),10*((IF(G29="Logarithm",LN(0.001+K29),IF(G29="Exponential",EXP(K29),K29)))-H29)/(I29-H29)),1))),"No data"))
A30: MoH/TFNC | B30: Vulnerability | C30: Vulnerable Groups / Children Health and Nutrition | D30: Neonatal mortality | E30: per 1,000 live births | F30: Adm1 | G30: None | H30: 10.05 | I30: 49.95 | J30: risk | L30: =IF(K30="","",IFERROR(MAX(0,MIN(10,ROUND(IF(J30="protective",10-10*((IF(G30="Logarithm",LN(0.001+K30),IF(G30="Exponential",EXP(K30),K30)))-H30)/(I30-H30),10*((IF(G30="Logarithm",LN(0.001+K30),IF(G30="Exponential",EXP(K30),K30)))-H30)/(I30-H30)),1))),"No data"))
A31: UNHCR/PMO-DMD | B31: Vulnerability | C31: Vulnerable Groups / Displaced People | D31: Internal Displaced People | E31: number of people | F31: Adm1 | G31: Logarithm | H31: -6.9077553 | I31: 10.311616 | J31: risk | L31: =IF(K31="","",IFERROR(MAX(0,MIN(10,ROUND(IF(J31="protective",10-10*((IF(G31="Logarithm",LN(0.001+K31),IF(G31="Exponential",EXP(K31),K31)))-H31)/(I31-H31),10*((IF(G31="Logarithm",LN(0.001+K31),IF(G31="Exponential",EXP(K31),K31)))-H31)/(I31-H31)),1))),"No data"))
A32: MoH | B32: Vulnerability | C32: Vulnerable Groups / Health Conditions | D32: Life Expectancy | E32: years | F32: National | G32: None | H32: 63.94 | I32: 72.08 | J32: protective | L32: =IF(K32="","",IFERROR(MAX(0,MIN(10,ROUND(IF(J32="protective",10-10*((IF(G32="Logarithm",LN(0.001+K32),IF(G32="Exponential",EXP(K32),K32)))-H32)/(I32-H32),10*((IF(G32="Logarithm",LN(0.001+K32),IF(G32="Exponential",EXP(K32),K32)))-H32)/(I32-H32)),1))),"No data"))
A33: MoH | B33: Vulnerability | C33: Vulnerable Groups / Health Conditions | D33: Malaria prevalence | E33: max malaria prevalence per person | F33: Adm1 | G33: None | H33: 0.11 | I33: 0.37 | J33: risk | L33: =IF(K33="","",IFERROR(MAX(0,MIN(10,ROUND(IF(J33="protective",10-10*((IF(G33="Logarithm",LN(0.001+K33),IF(G33="Exponential",EXP(K33),K33)))-H33)/(I33-H33),10*((IF(G33="Logarithm",LN(0.001+K33),IF(G33="Exponential",EXP(K33),K33)))-H33)/(I33-H33)),1))),"No data"))
A34: MoH | B34: Vulnerability | C34: Vulnerable Groups / Health Conditions | D34: Measles Incidence | E34: per 1,000,000 population | F34: National | G34: None | H34: 2.9 | I34: 1595.4 | J34: risk | L34: =IF(K34="","",IFERROR(MAX(0,MIN(10,ROUND(IF(J34="protective",10-10*((IF(G34="Logarithm",LN(0.001+K34),IF(G34="Exponential",EXP(K34),K34)))-H34)/(I34-H34),10*((IF(G34="Logarithm",LN(0.001+K34),IF(G34="Exponential",EXP(K34),K34)))-H34)/(I34-H34)),1))),"No data"))
A35: MoH | B35: Coping Capacity | C35: Infrastructure / Access to health care | D35: BCG Immunization Coverage | E35: % | F35: Adm1 | G35: None | H35: 90.4 | I35: 100 | J35: protective | L35: =IF(K35="","",IFERROR(MAX(0,MIN(10,ROUND(IF(J35="protective",10-10*((IF(G35="Logarithm",LN(0.001+K35),IF(G35="Exponential",EXP(K35),K35)))-H35)/(I35-H35),10*((IF(G35="Logarithm",LN(0.001+K35),IF(G35="Exponential",EXP(K35),K35)))-H35)/(I35-H35)),1))),"No data"))
... A39: MoH | B39: Coping Capacity | C39: Infrastructure / Access to health care | D39: Measles Immunization Coverage | E39: % | F39: Adm1 | G39: None | H39: 75.808875 | I39: 100 | J39: protective | L39: =IF(K39="","",IFERROR(MAX(0,MIN(10,ROUND(IF(J39="protective",10-10*((IF(G39="Logarithm",LN(0.001+K39),IF(G39="Exponential",EXP(K39),K39)))-H39)/(I39-H39),10*((IF(G39="Logarithm",LN(0.001+K39),IF(G39="Exponential",EXP(K39),K39)))-H39)/(I39-H39)),1))),"No data"))
A40: MoH | B40: Coping Capacity | C40: Infrastructure / Access to health care | D40: Physicians density | E40: per 10,000 population | F40: National | G40: None | H40: 0.5 | I40: 6.8 | J40: protective | L40: =IF(K40="","",IFERROR(MAX(0,MIN(10,ROUND(IF(J40="protective",10-10*((IF(G40="Logarithm",LN(0.001+MAX(MIN(K40,0.5),0.5)),IF(G40="Exponential",EXP(MAX(MIN(K40,0.5),0.5)),MAX(MIN(K40,0.5),0.5))))-H40)/(I40-H40),10*((IF(G40="Logarithm",LN(0.001+MAX(MIN(K40,0.5),0.5)),IF(G40="Exponential",EXP(MAX(MIN(K40,0.5),0.5)),MAX(MIN(K40,0.5),0.5))))-H40)/(I40-H40)),1))),"No data"))
A41: TCRA | B41: Coping Capacity | C41: Infrastructure / Communication | D41: Access to electricity | E41: % | F41: Adm1 | G41: None | H41: 8.7 | I41: 100 | J41: protective | L41: =IF(K41="","",IFERROR(MAX(0,MIN(10,ROUND(IF(J41="protective",10-10*((IF(G41="Logarithm",LN(0.001+K41),IF(G41="Exponential",EXP(K41),K41)))-H41)/(I41-H41),10*((IF(G41="Logarithm",LN(0.001+K41),IF(G41="Exponential",EXP(K41),K41)))-H41)/(I41-H41)),1))),"No data"))
A42: TCRA | B42: Coping Capacity | C42: Infrastructure / Communication | D42: Cellphone ownership | E42: % | F42: Adm1 | G42: None | H42: 57.09 | I42: 98.82 | J42: protective | L42: =IF(K42="","",IFERROR(MAX(0,MIN(10,ROUND(IF(J42="protective",10-10*((IF(G42="Logarithm",LN(0.001+K42),IF(G42="Exponential",EXP(K42),K42)))-H42)/(I42-H42),10*((IF(G42="Logarithm",LN(0.001+K42),IF(G42="Exponential",EXP(K42),K42)))-H42)/(I42-H42)),1))),"No data"))
A43: TCRA | B43: Coping Capacity | C43: Infrastructure / Communication | D43: Internet access | E43: % | F43: Adm1 | G43: None | H43: 0 | I43: 0 | J43: protective | L43: =IF(K43="","",IFERROR(MAX(0,MIN(10,ROUND(IF(J43="protective",10-10*((IF(G43="Logarithm",LN(0.001+K43),IF(G43="Exponential",EXP(K43),K43)))-H43)/(I43-H43),10*((IF(G43="Logarithm",LN(0.001+K43),IF(G43="Exponential",EXP(K43),K43)))-H43)/(I43-H43)),1))),"No data"))
A44: NBS/MoFP | B44: Coping Capacity | C44: Infrastructure / Economic capacity | D44: Gross National Income per capita | E44: Log - Thousands of US$ | F44: Adm1 | G44: None | H44: 7.29 | I44: 8.97 | J44: protective | L44: =IF(K44="","",IFERROR(MAX(0,MIN(10,ROUND(IF(J44="protective",10-10*((IF(G44="Logarithm",LN(0.001+K44),IF(G44="Exponential",EXP(K44),K44)))-H44)/(I44-H44),10*((IF(G44="Logarithm",LN(0.001+K44),IF(G44="Exponential",EXP(K44),K44)))-H44)/(I44-H44)),1))),"No data"))
A45: NBS/MoFP | B45: Coping Capacity | C45: Infrastructure / Economic capacity | D45: Household income | E45: US$ per capita | F45: National | G45: None | H45: 369.9 | I45: 12866.6 | J45: protective | L45: =IF(K45="","",IFERROR(MAX(0,MIN(10,ROUND(IF(J45="protective",10-10*((IF(G45="Logarithm",LN(0.001+K45),IF(G45="Exponential",EXP(K45),K45)))-H45)/(I45-H45),10*((IF(G45="Logarithm",LN(0.001+K45),IF(G45="Exponential",EXP(K45),K45)))-H45)/(I45-H45)),1))),"No data"))
A46: NBS/MoFP | B46: Coping Capacity | C46: Infrastructure / Economic capacity | D46: International Wealth Index | E46: index | F46: Adm1 | G46: None | H46: 19.11 | I46: 67.88 | J46: protective | L46: =IF(K46="","",IFERROR(MAX(0,MIN(10,ROUND(IF(J46="protective",10-10*((IF(G46="Logarithm",LN(0.001+K46),IF(G46="Exponential",EXP(K46),K46)))-H46)/(I46-H46),10*((IF(G46="Logarithm",LN(0.001+K46),IF(G46="Exponential",EXP(K46),K46)))-H46)/(I46-H46)),1))),"No data"))
A47: MoEST/NBS | B47: Coping Capacity | C47: Infrastructure / Education | D47: Adult literacy rate | E47: % | F47: National | G47: None | H47: 60 | I47: 96.2 | J47: protective | L47: =IF(K47="","",IFERROR(MAX(0,MIN(10,ROUND(IF(J47="protective",10-10*((IF(G47="Logarithm",LN(0.001+K47),IF(G47="Exponential",EXP(K47),K47)))-H47)/(I47-H47),10*((IF(G47="Logarithm",LN(0.001+K47),IF(G47="Exponential",EXP(K47),K47)))-H47)/(I47-H47)),1))),"No data"))
A48: MoEST/NBS | B48: Coping Capacity | C48: Infrastructure / Education | D48: Mean years at school | E48: years | F48: Adm1 | G48: None | H48: 3.94 | I48: 8.71 | J48: protective | L48: =IF(K48="","",IFERROR(MAX(0,MIN(10,ROUND(IF(J48="protective",10-10*((IF(G48="Logarithm",LN(0.001+K48),IF(G48="Exponential",EXP(K48),K48)))-H48)/(I48-H48),10*((IF(G48="Logarithm",LN(0.001+K48),IF(G48="Exponential",EXP(K48),K48)))-H48)/(I48-H48)),1))),"No data"))
A49: MoW | B49: Coping Capacity | C49: Infrastructure / WASH | D49: People using at least basic drinking water services (% of population) | E49: % | F49: National | G49: None | H49: 35 | I49: 99 | J49: protective | L49: =IF(K49="","",IFERROR(MAX(0,MIN(10,ROUND(IF(J49="protective",10-10*((IF(G49="Logarithm",LN(0.001+K49),IF(G49="Exponential",EXP(K49),K49)))-H49)/(I49-H49),10*((IF(G49="Logarithm",LN(0.001+K49),IF(G49="Exponential",EXP(K49),K49)))-H49)/(I49-H49)),1))),"No data"))
A50: MoW | B50: Coping Capacity | C50: Infrastructure / WASH | D50: People using at least basic sanitation services (% of population) | E50: % | F50: National | G50: None | H50: 15 | I50: 99 | J50: protective | L50: =IF(K50="","",IFERROR(MAX(0,MIN(10,ROUND(IF(J50="protective",10-10*((IF(G50="Logarithm",LN(0.001+K50),IF(G50="Exponential",EXP(K50),K50)))-H50)/(I50-H50),10*((IF(G50="Logarithm",LN(0.001+K50),IF(G50="Exponential",EXP(K50),K50)))-H50)/(I50-H50)),1))),"No data"))
A51: PMO-DMD | B51: Coping Capacity | C51: Institutional / DRR implementation | D51: Early Warning System | E51: number of people | F51: National | G51: None | H51: 0 | I51: 989030 | J51: protective | L51: =IF(K51="","",IFERROR(MAX(0,MIN(10,ROUND(IF(J51="protective",10-10*((IF(G51="Logarithm",LN(0.001+K51),IF(G51="Exponential",EXP(K51),K51)))-H51)/(I51-H51),10*((IF(G51="Logarithm",LN(0.001+K51),IF(G51="Exponential",EXP(K51),K51)))-H51)/(I51-H51)),1))),"No data"))
...

Sheet Council Entry
C1: Indicator | D1: Conflict Barometer | E1: GCRI derived Conflict probability | F1: Number of Events | G1: Number of Fatalities | H1: Coastal Erosion | I1: Historic Drought Frequency | J1: Earthquake exposure | K1: Deforestation - Treecover Loss | L1: Soil Erosion | M1: Flood exposure | N1: Landslide exposure | O1: Cyclone exposure - max speed | P1: Volcano exposure | Q1: Burned Area | R1: Fire Weather Index | S1: Gender Development Index | T1: Human Development Index | U1: Multidimensional Poverty Index | V1: Wealth Inequality | W1: Dependency Ratio | X1: Net ODA received (% of GNI) | Y1: Personal remittances | Z1: Population in informal settlements | AA1: Urban Population | AB1: Food Security - Insufficient food | AC1: Child mortality | AD1: Children Underweight | AE1: Infant mortality | AF1: Neonatal mortality | AG1: Internal Displaced People | AH1: Life Expectancy | AI1: Malaria prevalence | AJ1: Measles Incidence | AK1: BCG Immunization Coverage | AL1: DTP3 Immunization Coverage | AM1: Density of health facilities | AN1: Health expenditure per capita | AO1: Measles Immunization Coverage | AP1: Physicians density | AQ1: Access to electricity | AR1: Cellphone ownership | AS1: Internet access | AT1: Gross National Income per capita | AU1: Household income | AV1: International Wealth Index | AW1: Adult literacy rate | AX1: Mean years at school | AY1: People using at least basic drinking water services (% of population) | AZ1: People using at least basic sanitation services (% of population) | BA1: Early Warning System | BB1: Sendai Framework for Action | BC1: Government effectiveness | BD1: Subnational Corruption Index
C2: Unit | D2: Index | E2: % | F2: Number | G2: Number | H2: meters / year | I2: years | J2: index | K2: % | L2: Mg/ha/yr | M2: % | N2: % | O2: % | P2: index | Q2: % | R2: index | S2: index | T2: index | U2: index | V2: index | W2: ratio | X2: % | Y2: % | Z2: % | AA2: % | AB2: % pop phase 2 or higher | AC2: per 1,000 live births | AD2: % | AE2: per 1,000 live births | AF2: per 1,000 live births | AG2: number of people | AH2: years | AI2: max malaria prevalence per person | AJ2: per 1,000,000 population | AK2: % | AL2: % | AM2: per capita | AN2: US$ per capita | AO2: % | AP2: per 10,000 population | AQ2: % | AR2: % | AS2: % | AT2: Log - Thousands of US$ | AU2: US$ per capita | AV2: index | AW2: % | AX2: years | AY2: % | AZ2: % | BA2: number of people | BB2: index | BC2: index | BD2: index
C3: Sector | D3: PMO-DMD | E3: PMO-DMD | F3: TPF/PMO-DMD | G3: TPF/PMO-DMD | H3: TMA | I3: TMA | J3: TMA/GST | K3: NEMC | L3: NEMC | M3: PMO-DMD | N3: TMA | O3: TMA | P3: TMA/GST | Q3: TFS/TMA | R3: TFS/TMA | S3: NBS | T3: NBS | U3: NBS | V3: NBS | W3: NBS/MoFP | X3: NBS/MoFP | Y3: NBS/MoFP | Z3: NBS | AA3: NBS | AB3: MUCHALI/IPC | AC3: MoH/TFNC | AD3: MoH/TFNC | AE3: MoH/TFNC | AF3: MoH/TFNC | AG3: UNHCR/PMO-DMD | AH3: MoH | AI3: MoH | AJ3: MoH | AK3: MoH | AL3: MoH | AM3: MoH | AN3: MoH | AO3: MoH | AP3: MoH | AQ3: TCRA | AR3: TCRA | AS3: TCRA | AT3: NBS/MoFP | AU3: NBS/MoFP | AV3: NBS/MoFP | AW3: MoEST/NBS | AX3: MoEST/NBS | AY3: MoW | AZ3: MoW | BA3: PMO-DMD | BB3: PMO-DMD | BC3: PMO-DMD | BD3: PMO-DMD
C4: Transform | D4: None | E4: None | F4: Logarithm | G4: Logarithm | H4: None | I4: None | J4: None | K4: Logarithm | L4: None | M4: Logarithm | N4: Logarithm | O4: None | P4: None | Q4: None | R4: None | S4: None | T4: None | U4: None | V4: None | W4: None | X4: None | Y4: None | Z4: None | AA4: None | AB4: None | AC4: None | AD4: None | AE4: None | AF4: None | AG4: Logarithm | AH4: None | AI4: None | AJ4: None | AK4: None | AL4: None | AM4: None | AN4: None | AO4: None | AP4: None | AQ4: None | AR4: None | AS4: None | AT4: None | AU4: None | AV4: None | AW4: None | AX4: None | AY4: None | AZ4: None | BA4: None | BB4: None | BC4: None | BD4: None
C5: Ref Min | D5: 0 | E5: 0 | F5: 0.00099950033 | G5: -6.9077553 | H5: -0.3 | I5: 5 | J5: 0 | K5: -6.9077553 | L5: 1.7 | M5: -6.9077553 | N5: -6.9077553 | O5: 0 | P5: 0 | Q5: 0 | R5: 0 | S5: 0.91 | T5: 0.45 | U5: 0.132 | V5: 0.16 | W5: 55 | X5: 0.2 | Y5: 0 | Z5: 17 | AA5: 6.3 | AB5: 0 | AC5: 3.68 | AD5: 6.2 | AE5: 28.27 | AF5: 10.05 | AG5: -6.9077553 | AH5: 63.94 | AI5: 0.11 | AJ5: 2.9 | AK5: 90.4 | AL5: 69.9 | AM5: 0 | AN5: 19.3 | AO5: 75.808875 | AP5: 0.5 | AQ5: 8.7 | AR5: 57.09 | AS5: 0 | AT5: 7.29 | AU5: 369.9 | AV5: 19.11 | AW5: 60 | AX5: 3.94 | AY5: 35 | AZ5: 15 | BA5: 0 | BB5: 0 | BC5: -1.7 | BD5: 64.9
C6: Ref Max | D6: 5 | E6: 99.1 | F6: 4.0430688 | G6: 3.8918407 | H6: 0 | I6: 19 | J6: 1.0000001 | K6: -1.0023578 | L6: 15.9 | M6: -1.1488535 | N6: 0.00099950033 | O6: 18.10675 | P6: 4 | Q6: 49 | R6: 120 | S6: 0.97 | T6: 0.68 | U6: 0.39 | V6: 0.44 | W6: 121.8 | X6: 14.5 | Y6: 6.4 | Z6: 78.4 | AA6: 100 | AB6: 149 | AC6: 42.48 | AD6: 20 | AE6: 76.57 | AF6: 49.95 | AG6: 10.311616 | AH6: 72.08 | AI6: 0.37 | AJ6: 1595.4 | AK6: 100 | AL6: 98.6 | AM6: 0 | AN6: 758.2 | AO6: 100 | AP6: 6.8 | AQ6: 100 | AR6: 98.82 | AS6: 0 | AT6: 8.97 | AU6: 12866.6 | AV6: 67.88 | AW6: 96.2 | AX6: 8.71 | AY6: 99 | AZ6: 99 | BA6: 989030 | BB6: 1 | BC6: 0.8 | BD6: 79.5
C7: Direction | D7: Increase Risk | E7: Increase Risk | F7: Increase Risk | G7: Increase Risk | H7: Decrease Risk | I7: Increase Risk | J7: Increase Risk | K7: Increase Risk | L7: Increase Risk | M7: Increase Risk | N7: Increase Risk | O7: Increase Risk | P7: Increase Risk | Q7: Increase Risk | R7: Increase Risk | S7: Decrease Risk | T7: Decrease Risk | U7: Increase Risk | V7: Increase Risk | W7: Increase Risk | X7: Increase Risk | Y7: Increase Risk | Z7: Increase Risk | AA7: Increase Risk | AB7: Increase Risk | AC7: Increase Risk | AD7: Increase Risk | AE7: Increase Risk | AF7: Increase Risk | AG7: Increase Risk | AH7: Decrease Risk | AI7: Increase Risk | AJ7: Increase Risk | AK7: Decrease Risk | AL7: Decrease Risk | AM7: Decrease Risk | AN7: Decrease Risk | AO7: Decrease Risk | AP7: Decrease Risk | AQ7: Decrease Risk | AR7: Decrease Risk | AS7: Decrease Risk | AT7: Decrease Risk | AU7: Decrease Risk | AV7: Decrease Risk | AW7: Decrease Risk | AX7: Decrease Risk | AY7: Decrease Risk | AZ7: Decrease Risk | BA7: Decrease Risk | BB7: Decrease Risk | BC7: Decrease Risk | BD7: Decrease Risk
C8: Fence Lo | Y8: 0.67 | AP8: 0.5
C9: Fence Hi | Y9: 0.67 | AP9: 0.5
A10: Region | B10: Council | C10: Code | D10: Conflict Barometer | E10: GCRI derived Conflict probability | F10: Number of Events | G10: Number of Fatalities | H10: Coastal Erosion | I10: Historic Drought Frequency | J10: Earthquake exposure | K10: Deforestation - Treecover Loss | L10: Soil Erosion | M10: Flood exposure | N10: Landslide exposure | O10: Cyclone exposure - max speed | P10: Volcano exposure | Q10: Burned Area | R10: Fire Weather Index | S10: Gender Development Index | T10: Human Development Index | U10: Multidimensional Poverty Index | V10: Wealth Inequality | W10: Dependency Ratio | X10: Net ODA received (% of GNI) | Y10: Personal remittances | Z10: Population in informal settlements | AA10: Urban Population | AB10: Food Security - Insufficient food | AC10: Child mortality | AD10: Children Underweight | AE10: Infant mortality | AF10: Neonatal mortality | AG10: Internal Displaced People | AH10: Life Expectancy | AI10: Malaria prevalence | AJ10: Measles Incidence | AK10: BCG Immunization Coverage | AL10: DTP3 Immunization Coverage | AM10: Density of health facilities | AN10: Health expenditure per capita | AO10: Measles Immunization Coverage | AP10: Physicians density | AQ10: Access to electricity | AR10: Cellphone ownership | AS10: Internet access | AT10: Gross National Income per capita | AU10: Household income | AV10: International Wealth Index | AW10: Adult literacy rate | AX10: Mean years at school | AY10: People using at least basic drinking water services (% of population) | AZ10: People using at least basic sanitation services (% of population) | BA10: Early Warning System | BB10: Sendai Framework for Action | BC10: Government effectiveness | BD10: Subnational Corruption Index
A11: Arusha | B11: Arusha City | C11: C015
A12: Arusha | B12: Arusha District | C12: C011
A13: Arusha | B13: Karatu District | C13: C013
A14: Arusha | B14: Longido District | C14: C012
A15: Arusha | B15: Meru District | C15: C010
A16: Arusha | B16: Monduli District | C16: C009
A17: Arusha | B17: Ngorongoro District | C17: C014
A18: Dar es Salaam | B18: Dar Es Salaam City | C18: C053
A19: Dar es Salaam | B19: Kigamboni Municipal | C19: C055
A20: Dar es Salaam | B20: Kinondoni Municipal | C20: C052
A21: Dar es Salaam | B21: Temeke Municipal | C21: C054
A22: Dar es Salaam | B22: Ubungo Municipal | C22: C056
... A205: Tanga | B205: Tanga City | C205: C028

Sheet Council 0-10
A10: Region | B10: Council | C10: Code | D10: Conflict Barometer | E10: GCRI derived Conflict probability | F10: Number of Events | G10: Number of Fatalities | H10: Coastal Erosion | I10: Historic Drought Frequency | J10: Earthquake exposure | K10: Deforestation - Treecover Loss | L10: Soil Erosion | M10: Flood exposure | N10: Landslide exposure | O10: Cyclone exposure - max speed | P10: Volcano exposure | Q10: Burned Area | R10: Fire Weather Index | S10: Gender Development Index | T10: Human Development Index | U10: Multidimensional Poverty Index | V10: Wealth Inequality | W10: Dependency Ratio | X10: Net ODA received (% of GNI) | Y10: Personal remittances | Z10: Population in informal settlements | AA10: Urban Population | AB10: Food Security - Insufficient food | AC10: Child mortality | AD10: Children Underweight | AE10: Infant mortality | AF10: Neonatal mortality | AG10: Internal Displaced People | AH10: Life Expectancy | AI10: Malaria prevalence | AJ10: Measles Incidence | AK10: BCG Immunization Coverage | AL10: DTP3 Immunization Coverage | AM10: Density of health facilities | AN10: Health expenditure per capita | AO10: Measles Immunization Coverage | AP10: Physicians density | AQ10: Access to electricity | AR10: Cellphone ownership | AS10: Internet access | AT10: Gross National Income per capita | AU10: Household income | AV10: International Wealth Index | AW10: Adult literacy rate | AX10: Mean years at school | AY10: People using at least basic drinking water services (% of population) | AZ10: People using at least basic sanitation services (% of population) | BA10: Early Warning System | BB10: Sendai Framework for Action | BC10: Government effectiveness | BD10: Subnational Corruption Index
A11: Arusha | B11: Arusha City | C11: C015 | D11: =IF('Council Entry'!D11="","",IFERROR(MAX(0,MIN(10,ROUND(IF('Council Entry'!D$7="Decrease Risk",10-10*((IF('Council Entry'!D$4="Logarithm",LN(0.001+IF(AND(ISNUMBER('Council Entry'!D$8),ISNUMBER('Council Entry'!D$9)),MAX(MIN('Council Entry'!D11,'Council Entry'!D$9),'Council Entry'!D$8),'Council Entry'!D11)),IF('Council Entry'!D$4="Exponential",EXP(IF(AND(ISNUMBER('Council Entry'!D$8),ISNUMBER('Council Entry'!D$9)),MAX(MIN('Council Entry'!D11,'Council Entry'!D$9),'Council Entry'!D$8),'Council Entry'!D11)),IF(AND(ISNUMBER('Council Entry'!D$8),ISNUMBER('Council Entry'!D$9)),MAX(MIN('Council Entry'!D11,'Council Entry'!D$9),'Council Entry'!D$8),'Council Entry'!D11))))-'Council Entry'!D$5)/('Council Entry'!D$6-'Council Entry'!D$5),10*((IF('Council Entry'!D$4="Logarithm",LN(0.001+IF(AND(ISNUMBER('Council Entry'!D$8),ISNUMBER('Council Entry'!D$9)),MAX(MIN('Council Entry'!D11,'Council Entry'!D$9),'Council Entry'!D$8),'Council Entry'!D11)),IF('Council Entry'!D$4="Exponential",EXP(IF(AND(ISNUMBER('Council Entry'!D$8),ISNUMBER('Council Entry'!D$9)),MAX(MIN('Council Entry'!D11,'Council Entry'!D$9),'Council Entry'!D$8),'Council Entry'!D11)),IF(AND(ISNUMBER('Council Entry'!D$8),ISNUMBER('Council Entry'!D$9)),MAX(MIN('Council Entry'!D11,'Council Entry'!D$9),'Council Entry'!D$8),'Council Entry'!D11))))-'Council Entry'!D$5)/('Council Entry'!D$6-'Council Entry'!D$5)),1))),"No data")) | E11: =IF('Council Entry'!E11="","",IFERROR(MAX(0,MIN(10,ROUND(IF('Council Entry'!E$7="Decrease Risk",10-10*((IF('Council Entry'!E$4="Logarithm",LN(0.001+IF(AND(ISNUMBER('Council Entry'!E$8),ISNUMBER('Council Entry'!E$9)),MAX(MIN('Council Entry'!E11,'Council Entry'!E$9),'Council Entry'!E$8),'Council Entry'!E11)),IF('Council Entry'!E$4="Exponential",EXP(IF(AND(ISNUMBER('Council Entry'!E$8),ISNUMBER('Council Entry'!E$9)),MAX(MIN('Council Entry'!E11,'Council Entry'!E$9),'Council Entry'!E$8),'Council Entry'!E11)),IF(AND(ISNUMBER('Council Entry'!E$8),ISNUMBER('Council Entry'!E$9)),MAX(MIN('Council Entry'!E11,'Council Entry'!E$9),'Council Entry'!E$8),'Council Entry'!E11))))-'Council Entry'!E$5)/('Council Entry'!E$6-'Council Entry'!E$5),10*((IF('Council Entry'!E$4="Logarithm",LN(0.001+IF(AND(ISNUMBER('Council Entry'!E$8),ISNUMBER('Council Entry'!E$9)),MAX(MIN('Council Entry'!E11,'Council Entry'!E$9),'Council Entry'!E$8),'Council Entry'!E11)),IF('Council Entry'!E$4="Exponential",EXP(IF(AND(ISNUMBER('Council Entry'!E$8),ISNUMBER('Council Entry'!E$9)),MAX(MIN('Council Entry'!E11,'Council Entry'!E$9),'Council Entry'!E$8),'Council Entry'!E11)),IF(AND(ISNUMBER('Council Entry'!E$8),ISNUMBER('Council Entry'!E$9)),MAX(MIN('Council Entry'!E11,'Council Entry'!E$9),'Council Entry'!E$8),'Council Entry'!E11))))-'Council Entry'!E$5)/('Council Entry'!E$6-'Council Entry'!E$5)),1))),"No data")) | F11: =IF('Council Entry'!F11="","",IFERROR(MAX(0,MIN(10,ROUND(IF('Council Entry'!F$7="Decrease Risk",10-10*((IF('Council Entry'!F$4="Logarithm",LN(0.001+IF(AND(ISNUMBER('Council Entry'!F$8),ISNUMBER('Council Entry'!F$9)),MAX(MIN('Council Entry'!F11,'Council Entry'!F$9),'Council Entry'!F$8),'Council Entry'!F11)),IF('Council Entry'!F$4="Exponential",EXP(IF(AND(ISNUMBER('Council Entry'!F$8),ISNUMBER('Council Entry'!F$9)),MAX(MIN('Council Entry'!F11,'Council Entry'!F$9),'Council Entry'!F$8),'Council Entry'!F11)),IF(AND(ISNUMBER('Council Entry'!F$8),ISNUMBER('Council Entry'!F$9)),MAX(MIN('Council Entry'!F11,'Council Entry'!F$9),'Council Entry'!F$8),'Council Entry'!F11))))-'Council Entry'!F$5)/('Council Entry'!F$6-'Council Entry'!F$5),10*((IF('Council Entry'!F$4="Logarithm",LN(0.001+IF(AND(ISNUMBER('Council Entry'!F$8),ISNUMBER('Council Entry'!F$9)),MAX(MIN('Council Entry'!F11,'Council Entry'!F$9),'Council Entry'!F$8),'Council Entry'!F11)),IF('Council Entry'!F$4="Exponential",EXP(IF(AND(ISNUMBER('Council Entry'!F$8),ISNUMBER('Council Entry'!F$9)),MAX(MIN('Council Entry'!F11,'Council Entry'!F$9),'Council Entry'!F$8),'Council Entry'!F11)),IF(AND(ISNUMBER('Council Entry'!F$8),ISNUMBER('Council Entry'!F$9)),MAX(MIN('Council Entry'!F11,'Council Entry'!F$9),'Council Entry'!F$8),'Council Entry'!F11))))-'Council Entry'!F$5)/('Council Entry'!F$6-'Council Entry'!F$5)),1))),"No data")) | G11: =IF('Council Entry'!G11="","",IFERROR(MAX(0,MIN(10,ROUND(IF('Council Entry'!G$7="Decrease Risk",10-10*((IF('Council Entry'!G$4="Logarithm",LN(0.001+IF(AND(ISNUMBER('Council Entry'!G$8),ISNUMBER('Council Entry'!G$9)),MAX(MIN('Council Entry'!G11,'Council Entry'!G$9),'Council Entry'!G$8),'Council Entry'!G11)),IF('Council Entry'!G$4="Exponential",EXP(IF(AND(ISNUMBER('Council Entry'!G$8),ISNUMBER('Council Entry'!G$9)),MAX(MIN('Council Entry'!G11,'Council Entry'!G$9),'Council Entry'!G$8),'Council Entry'!G11)),IF(AND(ISNUMBER('Council Entry'!G$8),ISNUMBER('Council Entry'!G$9)),MAX(MIN('Council Entry'!G11,'Council Entry'!G$9),'Council Entry'!G$8),'Council Entry'!G11))))-'Council Entry'!G$5)/('Council Entry'!G$6-'Council Entry'!G$5),10*((IF('Council Entry'!G$4="Logarithm",LN(0.001+IF(AND(ISNUMBER('Council Entry'!G$8),ISNUMBER('Council Entry'!G$9)),MAX(MIN('Council Entry'!G11,'Council Entry'!G$9),'Council Entry'!G$8),'Council Entry'!G11)),IF('Council Entry'!G$4="Exponential",EXP(IF(AND(ISNUMBER('Council Entry'!G$8),ISNUMBER('Council Entry'!G$9)),MAX(MIN('Council Entry'!G11,'Council Entry'!G$9),'Council Entry'!G$8),'Council Entry'!G11)),IF(AND(ISNUMBER('Council Entry'!G$8),ISNUMBER('Council Entry'!G$9)),MAX(MIN('Council Entry'!G11,'Council Entry'!G$9),'Council Entry'!G$8),'Council Entry'!G11))))-'Council Entry'!G$5)/('Council Entry'!G$6-'Council Entry'!G$5)),1))),"No data")) | H11: =IF('Council Entry'!H11="","",IFERROR(MAX(0,MIN(10,ROUND(IF('Council Entry'!H$7="Decrease Risk",10-10*((IF('Council Entry'!H$4="Logarithm",LN(0.001+IF(AND(ISNUMBER('Council Entry'!H$8),ISNUMBER('Council Entry'!H$9)),MAX(MIN('Council Entry'!H11,'Council Entry'!H$9),'Council Entry'!H$8),'Council Entry'!H11)),IF('Council Entry'!H$4="Exponential",EXP(IF(AND(ISNUMBER('Council Entry'!H$8),ISNUMBER('Council Entry'!H$9)),MAX(MIN('Council Entry'!H11,'Council Entry'!H$9),'Council Entry'!H$8),'Council Entry'!H11)),IF(AND(ISNUMBER('Council Entry'!H$8),ISNUMBER('Council Entry'!H$9)),MAX(MIN('Council Entry'!H11,'Council Entry'!H$9),'Council Entry'!H$8),'Council Entry'!H11))))-'Council Entry'!H$5)/('Council Entry'!H$6-'Council Entry'!H$5),10*((IF('Council Entry'!H$4="Logarithm",LN(0.001+IF(AND(ISNUMBER('Council Entry'!H$8),ISNUMBER('Council Entry'!H$9)),MAX(MIN('Council Entry'!H11,'Council Entry'!H$9),'Council Entry'!H$8),'Council Entry'!H11)),IF('Council Entry'!H$4="Exponential",EXP(IF(AND(ISNUMBER('Council Entry'!H$8),ISNUMBER('Council Entry'!H$9)),MAX(MIN('Council Entry'!H11,'Council Entry'!H$9),'Council Entry'!H$8),'Council Entry'!H11)),IF(AND(ISNUMBER('Council Entry'!H$8),ISNUMBER('Council Entry'!H$9)),MAX(MIN('Council Entry'!H11,'Council Entry'!H$9),'Council Entry'!H$8),'Council Entry'!H11))))-'Council Entry'!H$5)/('Council Entry'!H$6-'Council Entry'!H$5)),1))),"No data")) | I11: =IF('Council Entry'!I11="","",IFERROR(MAX(0,MIN(10,ROUND(IF('Council Entry'!I$7="Decrease Risk",10-10*((IF('Council Entry'!I$4="Logarithm",LN(0.001+IF(AND(ISNUMBER('Council Entry'!I$8),ISNUMBER('Council Entry'!I$9)),MAX(MIN('Council Entry'!I11,'Council Entry'!I$9),'Council Entry'!I$8),'Council Entry'!I11)),IF('Council Entry'!I$4="Exponential",EXP(IF(AND(ISNUMBER('Council Entry'!I$8),ISNUMBER('Council Entry'!I$9)),MAX(MIN('Council Entry'!I11,'Council Entry'!I$9),'Council Entry'!I$8),'Council Entry'!I11)),IF(AND(ISNUMBER('Council Entry'!I$8),ISNUMBER('Council Entry'!I$9)),MAX(MIN('Council Entry'!I11,'Council Entry'!I$9),'Council Entry'!I$8),'Council Entry'!I11))))-'Council Entry'!I$5)/('Council Entry'!I$6-'Council Entry'!I$5),10*((IF('Council Entry'!I$4="Logarithm",LN(0.001+IF(AND(ISNUMBER('Council Entry'!I$8),ISNUMBER('Council Entry'!I$9)),MAX(MIN('Council Entry'!I11,'Council Entry'!I$9),'Council Entry'!I$8),'Council Entry'!I11)),IF('Council Entry'!I$4="Exponential",EXP(IF(AND(ISNUMBER('Council Entry'!I$8),ISNUMBER('Council Entry'!I$9)),MAX(MIN('Council Entry'!I11,'Council Entry'!I$9),'Council Entry'!I$8),'Council Entry'!I11)),IF(AND(ISNUMBER('Council Entry'!I$8),ISNUMBER('Council Entry'!I$9)),MAX(MIN('Council Entry'!I11,'Council Entry'!I$9),'Council Entry'!I$8),'Council Entry'!I11))))-'Council Entry'!I$5)/('Council Entry'!I$6-'Council Entry'!I$5)),1))),"No data")) | J11: =IF('Council Entry'!J11="","",IFERROR(MAX(0,MIN(10,ROUND(IF('Council Entry'!J$7="Decrease Risk",10-10*((IF('Council Entry'!J$4="Logarithm",LN(0.001+IF(AND(ISNUMBER('Council Entry'!J$8),ISNUMBER('Council Entry'!J$9)),MAX(MIN('Council Entry'!J11,'Council Entry'!J$9),'Council Entry'!J$8),'Council Entry'!J11)),IF('Council Entry'!J$4="Exponential",EXP(IF(AND(ISNUMBER('Council Entry'!J$8),ISNUMBER('Council Entry'!J$9)),MAX(MIN('Council Entry'!J11,'Council Entry'!J$9),'Council Entry'!J$8),'Council Entry'!J11)),IF(AND(ISNUMBER('Council Entry'!J$8),ISNUMBER('Council Entry'!J$9)),MAX(MIN('Council Entry'!J11,'Council Entry'!J$9),'Council Entry'!J$8),'Council Entry'!J11))))-'Council Entry'!J$5)/('Council Entry'!J$6-'Council Entry'!J$5),10*((IF('Council Entry'!J$4="Logarithm",LN(0.001+IF(AND(ISNUMBER('Council Entry'!J$8),ISNUMBER('Council Entry'!J$9)),MAX(MIN('Council Entry'!J11,'Council Entry'!J$9),'Council Entry'!J$8),'Council Entry'!J11)),IF('Council Entry'!J$4="Exponential",EXP(IF(AND(ISNUMBER('Council Entry'!J$8),ISNUMBER('Council Entry'!J$9)),MAX(MIN('Council Entry'!J11,'Council Entry'!J$9),'Council Entry'!J$8),'Council Entry'!J11)),IF(AND(ISNUMBER('Council Entry'!J$8),ISNUMBER('Council Entry'!J$9)),MAX(MIN('Council Entry'!J11,'Council Entry'!J$9),'Council Entry'!J$8),'Council Entry'!J11))))-'Council Entry'!J$5)/('Council Entry'!J$6-'Council Entry'!J$5)),1))),"No data")) | K11: =IF('Council Entry'!K11="","",IFERROR(MAX(0,MIN(10,ROUND(IF('Council Entry'!K$7="Decrease Risk",10-10*((IF('Council Entry'!K$4="Logarithm",LN(0.001+IF(AND(ISNUMBER('Council Entry'!K$8),ISNUMBER('Council Entry'!K$9)),MAX(MIN('Council Entry'!K11,'Council Entry'!K$9),'Council Entry'!K$8),'Council Entry'!K11)),IF('Council Entry'!K$4="Exponential",EXP(IF(AND(ISNUMBER('Council Entry'!K$8),ISNUMBER('Council Entry'!K$9)),MAX(MIN('Council Entry'!K11,'Council Entry'!K$9),'Council Entry'!K$8),'Council Entry'!K11)),IF(AND(ISNUMBER('Council Entry'!K$8),ISNUMBER('Council Entry'!K$9)),MAX(MIN('Council Entry'!K11,'Council Entry'!K$9),'Council Entry'!K$8),'Council Entry'!K11))))-'Council Entry'!K$5)/('Council Entry'!K$6-'Council Entry'!K$5),10*((IF('Council Entry'!K$4="Logarithm",LN(0.001+IF(AND(ISNUMBER('Council Entry'!K$8),ISNUMBER('Council Entry'!K$9)),MAX(MIN('Council Entry'!K11,'Council Entry'!K$9),'Council Entry'!K$8),'Council Entry'!K11)),IF('Council Entry'!K$4="Exponential",EXP(IF(AND(ISNUMBER('Council Entry'!K$8),ISNUMBER('Council Entry'!K$9)),MAX(MIN('Council Entry'!K11,'Council Entry'!K$9),'Council Entry'!K$8),'Council Entry'!K11)),IF(AND(ISNUMBER('Council Entry'!K$8),ISNUMBER('Council Entry'!K$9)),MAX(MIN('Council Entry'!K11,'Council Entry'!K$9),'Council Entry'!K$8),'Council Entry'!K11))))-'Council Entry'!K$5)/('Council Entry'!K$6-'Council Entry'!K$5)),1))),"No data")) | ... BD11: =IF('Council Entry'!BD11="","",IFERROR(MAX(0,MIN(10,ROUND(IF('Council Entry'!BD$7="Decrease Risk",10-10*((IF('Council Entry'!BD$4="Logarithm",LN(0.001+IF(AND(ISNUMBER('Council Entry'!BD$8),ISNUMBER('Council Entry'!BD$9)),MAX(MIN('Council Entry'!BD11,'Council Entry'!BD$9),'Council Entry'!BD$8),'Council Entry'!BD11)),IF('Council Entry'!BD$4="Exponential",EXP(IF(AND(ISNUMBER('Council Entry'!BD$8),ISNUMBER('Council Entry'!BD$9)),MAX(MIN('Council Entry'!BD11,'Council Entry'!BD$9),'Council Entry'!BD$8),'Council Entry'!BD11)),IF(AND(ISNUMBER('Council Entry'!BD$8),ISNUMBER('Council Entry'!BD$9)),MAX(MIN('Council Entry'!BD11,'Council Entry'!BD$9),'Council Entry'!BD$8),'Council Entry'!BD11))))-'Council Entry'!BD$5)/('Council Entry'!BD$6-'Council Entry'!BD$5),10*((IF('Council Entry'!BD$4="Logarithm",LN(0.001+IF(AND(ISNUMBER('Council Entry'!BD$8),ISNUMBER('Council Entry'!BD$9)),MAX(MIN('Council Entry'!BD11,'Council Entry'!BD$9),'Council Entry'!BD$8),'Council Entry'!BD11)),IF('Council Entry'!BD$4="Exponential",EXP(IF(AND(ISNUMBER('Council Entry'!BD$8),ISNUMBER('Council Entry'!BD$9)),MAX(MIN('Council Entry'!BD11,'Council Entry'!BD$9),'Council Entry'!BD$8),'Council Entry'!BD11)),IF(AND(ISNUMBER('Council Entry'!BD$8),ISNUMBER('Council Entry'!BD$9)),MAX(MIN('Council Entry'!BD11,'Council Entry'!BD$9),'Council Entry'!BD$8),'Council Entry'!BD11))))-'Council Entry'!BD$5)/('Council Entry'!BD$6-'Council Entry'!BD$5)),1))),"No data"))
A12: Arusha | B12: Arusha District | C12: C011 | D12: =IF('Council Entry'!D12="","",IFERROR(MAX(0,MIN(10,ROUND(IF('Council Entry'!D$7="Decrease Risk",10-10*((IF('Council Entry'!D$4="Logarithm",LN(0.001+IF(AND(ISNUMBER('Council Entry'!D$8),ISNUMBER('Council Entry'!D$9)),MAX(MIN('Council Entry'!D12,'Council Entry'!D$9),'Council Entry'!D$8),'Council Entry'!D12)),IF('Council Entry'!D$4="Exponential",EXP(IF(AND(ISNUMBER('Council Entry'!D$8),ISNUMBER('Council Entry'!D$9)),MAX(MIN('Council Entry'!D12,'Council Entry'!D$9),'Council Entry'!D$8),'Council Entry'!D12)),IF(AND(ISNUMBER('Council Entry'!D$8),ISNUMBER('Council Entry'!D$9)),MAX(MIN('Council Entry'!D12,'Council Entry'!D$9),'Council Entry'!D$8),'Council Entry'!D12))))-'Council Entry'!D$5)/('Council Entry'!D$6-'Council Entry'!D$5),10*((IF('Council Entry'!D$4="Logarithm",LN(0.001+IF(AND(ISNUMBER('Council Entry'!D$8),ISNUMBER('Council Entry'!D$9)),MAX(MIN('Council Entry'!D12,'Council Entry'!D$9),'Council Entry'!D$8),'Council Entry'!D12)),IF('Council Entry'!D$4="Exponential",EXP(IF(AND(ISNUMBER('Council Entry'!D$8),ISNUMBER('Council Entry'!D$9)),MAX(MIN('Council Entry'!D12,'Council Entry'!D$9),'Council Entry'!D$8),'Council Entry'!D12)),IF(AND(ISNUMBER('Council Entry'!D$8),ISNUMBER('Council Entry'!D$9)),MAX(MIN('Council Entry'!D12,'Council Entry'!D$9),'Council Entry'!D$8),'Council Entry'!D12))))-'Council Entry'!D$5)/('Council Entry'!D$6-'Council Entry'!D$5)),1))),"No data")) | E12: =IF('Council Entry'!E12="","",IFERROR(MAX(0,MIN(10,ROUND(IF('Council Entry'!E$7="Decrease Risk",10-10*((IF('Council Entry'!E$4="Logarithm",LN(0.001+IF(AND(ISNUMBER('Council Entry'!E$8),ISNUMBER('Council Entry'!E$9)),MAX(MIN('Council Entry'!E12,'Council Entry'!E$9),'Council Entry'!E$8),'Council Entry'!E12)),IF('Council Entry'!E$4="Exponential",EXP(IF(AND(ISNUMBER('Council Entry'!E$8),ISNUMBER('Council Entry'!E$9)),MAX(MIN('Council Entry'!E12,'Council Entry'!E$9),'Council Entry'!E$8),'Council Entry'!E12)),IF(AND(ISNUMBER('Council Entry'!E$8),ISNUMBER('Council Entry'!E$9)),MAX(MIN('Council Entry'!E12,'Council Entry'!E$9),'Council Entry'!E$8),'Council Entry'!E12))))-'Council Entry'!E$5)/('Council Entry'!E$6-'Council Entry'!E$5),10*((IF('Council Entry'!E$4="Logarithm",LN(0.001+IF(AND(ISNUMBER('Council Entry'!E$8),ISNUMBER('Council Entry'!E$9)),MAX(MIN('Council Entry'!E12,'Council Entry'!E$9),'Council Entry'!E$8),'Council Entry'!E12)),IF('Council Entry'!E$4="Exponential",EXP(IF(AND(ISNUMBER('Council Entry'!E$8),ISNUMBER('Council Entry'!E$9)),MAX(MIN('Council Entry'!E12,'Council Entry'!E$9),'Council Entry'!E$8),'Council Entry'!E12)),IF(AND(ISNUMBER('Council Entry'!E$8),ISNUMBER('Council Entry'!E$9)),MAX(MIN('Council Entry'!E12,'Council Entry'!E$9),'Council Entry'!E$8),'Council Entry'!E12))))-'Council Entry'!E$5)/('Council Entry'!E$6-'Council Entry'!E$5)),1))),"No data")) | F12: =IF('Council Entry'!F12="","",IFERROR(MAX(0,MIN(10,ROUND(IF('Council Entry'!F$7="Decrease Risk",10-10*((IF('Council Entry'!F$4="Logarithm",LN(0.001+IF(AND(ISNUMBER('Council Entry'!F$8),ISNUMBER('Council Entry'!F$9)),MAX(MIN('Council Entry'!F12,'Council Entry'!F$9),'Council Entry'!F$8),'Council Entry'!F12)),IF('Council Entry'!F$4="Exponential",EXP(IF(AND(ISNUMBER('Council Entry'!F$8),ISNUMBER('Council Entry'!F$9)),MAX(MIN('Council Entry'!F12,'Council Entry'!F$9),'Council Entry'!F$8),'Council Entry'!F12)),IF(AND(ISNUMBER('Council Entry'!F$8),ISNUMBER('Council Entry'!F$9)),MAX(MIN('Council Entry'!F12,'Council Entry'!F$9),'Council Entry'!F$8),'Council Entry'!F12))))-'Council Entry'!F$5)/('Council Entry'!F$6-'Council Entry'!F$5),10*((IF('Council Entry'!F$4="Logarithm",LN(0.001+IF(AND(ISNUMBER('Council Entry'!F$8),ISNUMBER('Council Entry'!F$9)),MAX(MIN('Council Entry'!F12,'Council Entry'!F$9),'Council Entry'!F$8),'Council Entry'!F12)),IF('Council Entry'!F$4="Exponential",EXP(IF(AND(ISNUMBER('Council Entry'!F$8),ISNUMBER('Council Entry'!F$9)),MAX(MIN('Council Entry'!F12,'Council Entry'!F$9),'Council Entry'!F$8),'Council Entry'!F12)),IF(AND(ISNUMBER('Council Entry'!F$8),ISNUMBER('Council Entry'!F$9)),MAX(MIN('Council Entry'!F12,'Council Entry'!F$9),'Council Entry'!F$8),'Council Entry'!F12))))-'Council Entry'!F$5)/('Council Entry'!F$6-'Council Entry'!F$5)),1))),"No data")) | G12: =IF('Council Entry'!G12="","",IFERROR(MAX(0,MIN(10,ROUND(IF('Council Entry'!G$7="Decrease Risk",10-10*((IF('Council Entry'!G$4="Logarithm",LN(0.001+IF(AND(ISNUMBER('Council Entry'!G$8),ISNUMBER('Council Entry'!G$9)),MAX(MIN('Council Entry'!G12,'Council Entry'!G$9),'Council Entry'!G$8),'Council Entry'!G12)),IF('Council Entry'!G$4="Exponential",EXP(IF(AND(ISNUMBER('Council Entry'!G$8),ISNUMBER('Council Entry'!G$9)),MAX(MIN('Council Entry'!G12,'Council Entry'!G$9),'Council Entry'!G$8),'Council Entry'!G12)),IF(AND(ISNUMBER('Council Entry'!G$8),ISNUMBER('Council Entry'!G$9)),MAX(MIN('Council Entry'!G12,'Council Entry'!G$9),'Council Entry'!G$8),'Council Entry'!G12))))-'Council Entry'!G$5)/('Council Entry'!G$6-'Council Entry'!G$5),10*((IF('Council Entry'!G$4="Logarithm",LN(0.001+IF(AND(ISNUMBER('Council Entry'!G$8),ISNUMBER('Council Entry'!G$9)),MAX(MIN('Council Entry'!G12,'Council Entry'!G$9),'Council Entry'!G$8),'Council Entry'!G12)),IF('Council Entry'!G$4="Exponential",EXP(IF(AND(ISNUMBER('Council Entry'!G$8),ISNUMBER('Council Entry'!G$9)),MAX(MIN('Council Entry'!G12,'Council Entry'!G$9),'Council Entry'!G$8),'Council Entry'!G12)),IF(AND(ISNUMBER('Council Entry'!G$8),ISNUMBER('Council Entry'!G$9)),MAX(MIN('Council Entry'!G12,'Council Entry'!G$9),'Council Entry'!G$8),'Council Entry'!G12))))-'Council Entry'!G$5)/('Council Entry'!G$6-'Council Entry'!G$5)),1))),"No data")) | H12: =IF('Council Entry'!H12="","",IFERROR(MAX(0,MIN(10,ROUND(IF('Council Entry'!H$7="Decrease Risk",10-10*((IF('Council Entry'!H$4="Logarithm",LN(0.001+IF(AND(ISNUMBER('Council Entry'!H$8),ISNUMBER('Council Entry'!H$9)),MAX(MIN('Council Entry'!H12,'Council Entry'!H$9),'Council Entry'!H$8),'Council Entry'!H12)),IF('Council Entry'!H$4="Exponential",EXP(IF(AND(ISNUMBER('Council Entry'!H$8),ISNUMBER('Council Entry'!H$9)),MAX(MIN('Council Entry'!H12,'Council Entry'!H$9),'Council Entry'!H$8),'Council Entry'!H12)),IF(AND(ISNUMBER('Council Entry'!H$8),ISNUMBER('Council Entry'!H$9)),MAX(MIN('Council Entry'!H12,'Council Entry'!H$9),'Council Entry'!H$8),'Council Entry'!H12))))-'Council Entry'!H$5)/('Council Entry'!H$6-'Council Entry'!H$5),10*((IF('Council Entry'!H$4="Logarithm",LN(0.001+IF(AND(ISNUMBER('Council Entry'!H$8),ISNUMBER('Council Entry'!H$9)),MAX(MIN('Council Entry'!H12,'Council Entry'!H$9),'Council Entry'!H$8),'Council Entry'!H12)),IF('Council Entry'!H$4="Exponential",EXP(IF(AND(ISNUMBER('Council Entry'!H$8),ISNUMBER('Council Entry'!H$9)),MAX(MIN('Council Entry'!H12,'Council Entry'!H$9),'Council Entry'!H$8),'Council Entry'!H12)),IF(AND(ISNUMBER('Council Entry'!H$8),ISNUMBER('Council Entry'!H$9)),MAX(MIN('Council Entry'!H12,'Council Entry'!H$9),'Council Entry'!H$8),'Council Entry'!H12))))-'Council Entry'!H$5)/('Council Entry'!H$6-'Council Entry'!H$5)),1))),"No data")) | I12: =IF('Council Entry'!I12="","",IFERROR(MAX(0,MIN(10,ROUND(IF('Council Entry'!I$7="Decrease Risk",10-10*((IF('Council Entry'!I$4="Logarithm",LN(0.001+IF(AND(ISNUMBER('Council Entry'!I$8),ISNUMBER('Council Entry'!I$9)),MAX(MIN('Council Entry'!I12,'Council Entry'!I$9),'Council Entry'!I$8),'Council Entry'!I12)),IF('Council Entry'!I$4="Exponential",EXP(IF(AND(ISNUMBER('Council Entry'!I$8),ISNUMBER('Council Entry'!I$9)),MAX(MIN('Council Entry'!I12,'Council Entry'!I$9),'Council Entry'!I$8),'Council Entry'!I12)),IF(AND(ISNUMBER('Council Entry'!I$8),ISNUMBER('Council Entry'!I$9)),MAX(MIN('Council Entry'!I12,'Council Entry'!I$9),'Council Entry'!I$8),'Council Entry'!I12))))-'Council Entry'!I$5)/('Council Entry'!I$6-'Council Entry'!I$5),10*((IF('Council Entry'!I$4="Logarithm",LN(0.001+IF(AND(ISNUMBER('Council Entry'!I$8),ISNUMBER('Council Entry'!I$9)),MAX(MIN('Council Entry'!I12,'Council Entry'!I$9),'Council Entry'!I$8),'Council Entry'!I12)),IF('Council Entry'!I$4="Exponential",EXP(IF(AND(ISNUMBER('Council Entry'!I$8),ISNUMBER('Council Entry'!I$9)),MAX(MIN('Council Entry'!I12,'Council Entry'!I$9),'Council Entry'!I$8),'Council Entry'!I12)),IF(AND(ISNUMBER('Council Entry'!I$8),ISNUMBER('Council Entry'!I$9)),MAX(MIN('Council Entry'!I12,'Council Entry'!I$9),'Council Entry'!I$8),'Council Entry'!I12))))-'Council Entry'!I$5)/('Council Entry'!I$6-'Council Entry'!I$5)),1))),"No data")) | J12: =IF('Council Entry'!J12="","",IFERROR(MAX(0,MIN(10,ROUND(IF('Council Entry'!J$7="Decrease Risk",10-10*((IF('Council Entry'!J$4="Logarithm",LN(0.001+IF(AND(ISNUMBER('Council Entry'!J$8),ISNUMBER('Council Entry'!J$9)),MAX(MIN('Council Entry'!J12,'Council Entry'!J$9),'Council Entry'!J$8),'Council Entry'!J12)),IF('Council Entry'!J$4="Exponential",EXP(IF(AND(ISNUMBER('Council Entry'!J$8),ISNUMBER('Council Entry'!J$9)),MAX(MIN('Council Entry'!J12,'Council Entry'!J$9),'Council Entry'!J$8),'Council Entry'!J12)),IF(AND(ISNUMBER('Council Entry'!J$8),ISNUMBER('Council Entry'!J$9)),MAX(MIN('Council Entry'!J12,'Council Entry'!J$9),'Council Entry'!J$8),'Council Entry'!J12))))-'Council Entry'!J$5)/('Council Entry'!J$6-'Council Entry'!J$5),10*((IF('Council Entry'!J$4="Logarithm",LN(0.001+IF(AND(ISNUMBER('Council Entry'!J$8),ISNUMBER('Council Entry'!J$9)),MAX(MIN('Council Entry'!J12,'Council Entry'!J$9),'Council Entry'!J$8),'Council Entry'!J12)),IF('Council Entry'!J$4="Exponential",EXP(IF(AND(ISNUMBER('Council Entry'!J$8),ISNUMBER('Council Entry'!J$9)),MAX(MIN('Council Entry'!J12,'Council Entry'!J$9),'Council Entry'!J$8),'Council Entry'!J12)),IF(AND(ISNUMBER('Council Entry'!J$8),ISNUMBER('Council Entry'!J$9)),MAX(MIN('Council Entry'!J12,'Council Entry'!J$9),'Council Entry'!J$8),'Council Entry'!J12))))-'Council Entry'!J$5)/('Council Entry'!J$6-'Council Entry'!J$5)),1))),"No data")) | K12: =IF('Council Entry'!K12="","",IFERROR(MAX(0,MIN(10,ROUND(IF('Council Entry'!K$7="Decrease Risk",10-10*((IF('Council Entry'!K$4="Logarithm",LN(0.001+IF(AND(ISNUMBER('Council Entry'!K$8),ISNUMBER('Council Entry'!K$9)),MAX(MIN('Council Entry'!K12,'Council Entry'!K$9),'Council Entry'!K$8),'Council Entry'!K12)),IF('Council Entry'!K$4="Exponential",EXP(IF(AND(ISNUMBER('Council Entry'!K$8),ISNUMBER('Council Entry'!K$9)),MAX(MIN('Council Entry'!K12,'Council Entry'!K$9),'Council Entry'!K$8),'Council Entry'!K12)),IF(AND(ISNUMBER('Council Entry'!K$8),ISNUMBER('Council Entry'!K$9)),MAX(MIN('Council Entry'!K12,'Council Entry'!K$9),'Council Entry'!K$8),'Council Entry'!K12))))-'Council Entry'!K$5)/('Council Entry'!K$6-'Council Entry'!K$5),10*((IF('Council Entry'!K$4="Logarithm",LN(0.001+IF(AND(ISNUMBER('Council Entry'!K$8),ISNUMBER('Council Entry'!K$9)),MAX(MIN('Council Entry'!K12,'Council Entry'!K$9),'Council Entry'!K$8),'Council Entry'!K12)),IF('Council Entry'!K$4="Exponential",EXP(IF(AND(ISNUMBER('Council Entry'!K$8),ISNUMBER('Council Entry'!K$9)),MAX(MIN('Council Entry'!K12,'Council Entry'!K$9),'Council Entry'!K$8),'Council Entry'!K12)),IF(AND(ISNUMBER('Council Entry'!K$8),ISNUMBER('Council Entry'!K$9)),MAX(MIN('Council Entry'!K12,'Council Entry'!K$9),'Council Entry'!K$8),'Council Entry'!K12))))-'Council Entry'!K$5)/('Council Entry'!K$6-'Council Entry'!K$5)),1))),"No data")) | ... BD12: =IF('Council Entry'!BD12="","",IFERROR(MAX(0,MIN(10,ROUND(IF('Council Entry'!BD$7="Decrease Risk",10-10*((IF('Council Entry'!BD$4="Logarithm",LN(0.001+IF(AND(ISNUMBER('Council Entry'!BD$8),ISNUMBER('Council Entry'!BD$9)),MAX(MIN('Council Entry'!BD12,'Council Entry'!BD$9),'Council Entry'!BD$8),'Council Entry'!BD12)),IF('Council Entry'!BD$4="Exponential",EXP(IF(AND(ISNUMBER('Council Entry'!BD$8),ISNUMBER('Council Entry'!BD$9)),MAX(MIN('Council Entry'!BD12,'Council Entry'!BD$9),'Council Entry'!BD$8),'Council Entry'!BD12)),IF(AND(ISNUMBER('Council Entry'!BD$8),ISNUMBER('Council Entry'!BD$9)),MAX(MIN('Council Entry'!BD12,'Council Entry'!BD$9),'Council Entry'!BD$8),'Council Entry'!BD12))))-'Council Entry'!BD$5)/('Council Entry'!BD$6-'Council Entry'!BD$5),10*((IF('Council Entry'!BD$4="Logarithm",LN(0.001+IF(AND(ISNUMBER('Council Entry'!BD$8),ISNUMBER('Council Entry'!BD$9)),MAX(MIN('Council Entry'!BD12,'Council Entry'!BD$9),'Council Entry'!BD$8),'Council Entry'!BD12)),IF('Council Entry'!BD$4="Exponential",EXP(IF(AND(ISNUMBER('Council Entry'!BD$8),ISNUMBER('Council Entry'!BD$9)),MAX(MIN('Council Entry'!BD12,'Council Entry'!BD$9),'Council Entry'!BD$8),'Council Entry'!BD12)),IF(AND(ISNUMBER('Council Entry'!BD$8),ISNUMBER('Council Entry'!BD$9)),MAX(MIN('Council Entry'!BD12,'Council Entry'!BD$9),'Council Entry'!BD$8),'Council Entry'!BD12))))-'Council Entry'!BD$5)/('Council Entry'!BD$6-'Council Entry'!BD$5)),1))),"No data"))
