Workbook

Sheet How to use
A1: INFORM Tanzania - ADVANCED Data Collection Tool (v2, EXPLODED multi-source)
A3: This workbook is SEPARATE from the shared NORMAL tool. Here each hazard is EXPLODED into every
A4: institution that holds relevant evidence - each with its OWN cell, in its own unit.
A6: Drought = TMA (SPEI, aridity, rainfall variability) + MoA (season-failure, NDVI, soil) + MoW (water levels)
A7: Flood = TMA (>50 / >100 mm days) + MoW (river peak) + BWB (basin flood records) + PMO-DMD (events)
A8: Landslide = GST (susceptibility hotspots) + TMA (triggering rainfall)
A9: Coastal = TMA (waves, onshore wind, storm surge) + NEMC (shoreline erosion, mangrove loss)
A10: Storms / Earthquake / Heatwave / Lightning likewise.
A12: 1. Find YOUR institution's coloured columns on the "Advanced Entry" sheet (the Owner row names them).
A13: 2. Type the ACTUAL VALUE where you have it. Leave BLANK where you do not - a blank is SKIPPED.
A14: 3. "Advanced 0-10" standardises each cell (the proven INFORM pipeline, locked).
A15: 4. "Components" aggregates each basket by WEIGHTED AVERAGE over the cells PRESENT - so a missing
... A20: validated. Nothing here replaces the regional INFORM - it refines it where local data exists.

Sheet Advanced Entry
C1: Indicator | D1: SPEI-12 drought depth | E1: Aridity (P/PET) | F1: Rainfall variability (CV) | G1: Growing-season failure frequency | H1: Vegetation/biomass anomaly (NDVI z) | I1: Soil moisture | J1: Water levels (% of normal) | K1: Extreme wet days (>50 mm) | L1: Very-heavy days (>100 mm) | M1: River peak above normal | N1: Basin flood records | O1: Recorded flood impact events | P1: Landslide susceptibility | Q1: Triggering rainfall (max 5-day) | R1: Cyclone/strong-wind frequency | S1: Extreme wind speed | T1: Seismic hazard (PGA 475-yr) | U1: Historical seismicity density | V1: Significant wave height (Hs 99th pct) | W1: Extreme onshore wind | X1: Storm-surge frequency | Y1: Shoreline retreat / erosion rate | Z1: Mangrove loss (protective buffer) | AA1: Heat-health days (> 90th pct Tmax) | AB1: Flash density
C2: Owner | D2: TMA | E2: TMA | F2: TMA | G2: MoA | H2: MoA | I2: MoA | J2: MoW | K2: TMA | L2: TMA | M2: MoW | N2: BWB | O2: PMO-DMD | P2: GST | Q2: TMA | R2: TMA | S2: TMA | T2: GST | U2: GST | V2: TMA | W2: TMA | X2: TMA | Y2: NEMC | Z2: NEMC | AA2: TMA | AB2: TMA
C3: Component | D3: Drought | E3: Drought | F3: Drought | G3: Drought | H3: Drought | I3: Drought | J3: Drought | K3: Flood | L3: Flood | M3: Flood | N3: Flood | O3: Flood | P3: Landslide | Q3: Landslide | R3: Storms & Cyclone | S3: Storms & Cyclone | T3: Earthquake | U3: Earthquake | V3: Coastal hazards | W3: Coastal hazards | X3: Coastal hazards | Y3: Coastal hazards | Z3: Coastal hazards | AA3: Heatwave | AB3: Lightning
C4: Unit | D4: index | E4: ratio | F4: ratio | G4: fraction | H4: index | I4: % | J4: % | K4: days/yr | L4: days/yr | M4: m | N4: events/decade | O4: events/decade | P4: index 0-1 | Q4: mm | R4: events/decade | S4: m/s | T4: g | U4: events/100yr | V4: m | W4: m/s | X4: events/decade | Y4: m/yr | Z4: %/decade | AA4: days/yr | AB4: flashes/km2/yr
C5: Transform | D5: None | E5: None | F5: None | G5: None | H5: None | I5: None | J5: None | K5: None | L5: None | M5: None | N5: None | O5: None | P5: None | Q5: None | R5: None | S5: None | T5: None | U5: None | V5: None | W5: None | X5: None | Y5: None | Z5: None | AA5: None | AB5: None
C6: Ref Min | D6: 0 | E6: 0 | F6: 0.1 | G6: 0 | H6: -2 | I6: 0 | J6: 0 | K6: 0 | L6: 0 | M6: 0 | N6: 0 | O6: 0 | P6: 0 | Q6: 0 | R6: 0 | S6: 10 | T6: 0 | U6: 0 | V6: 0 | W6: 10 | X6: 0 | Y6: 0 | Z6: 0 | AA6: 0 | AB6: 0
C7: Ref Max | D7: 3 | E7: 0.65 | F7: 0.35 | G7: 0.5 | H7: 1 | I7: 50 | J7: 100 | K7: 20 | L7: 8 | M7: 5 | N7: 10 | O7: 10 | P7: 1 | Q7: 300 | R7: 8 | S7: 35 | T7: 0.4 | U7: 50 | V7: 4 | W7: 30 | X7: 8 | Y7: 5 | Z7: 30 | AA7: 60 | AB7: 30
C8: Direction | D8: Increase Risk | E8: Decrease Risk | F8: Increase Risk | G8: Increase Risk | H8: Decrease Risk | I8: Decrease Risk | J8: Decrease Risk | K8: Increase Risk | L8: Increase Risk | M8: Increase Risk | N8: Increase Risk | O8: Increase Risk | P8: Increase Risk | Q8: Increase Risk | R8: Increase Risk | S8: Increase Risk | T8: Increase Risk | U8: Increase Risk | V8: Increase Risk | W8: Increase Risk | X8: Increase Risk | Y8: Increase Risk | Z8: Increase Risk | AA8: Increase Risk | AB8: Increase Risk
C9: Weight | D9: 0.25 | E9: 0.15 | F9: 0.15 | G9: 0.2 | H9: 0.1 | I9: 0.1 | J9: 0.05 | K9: 0.3 | L9: 0.15 | M9: 0.2 | N9: 0.2 | O9: 0.15 | P9: 0.55 | Q9: 0.45 | R9: 0.6 | S9: 0.4 | T9: 0.7 | U9: 0.3 | V9: 0.25 | W9: 0.2 | X9: 0.2 | Y9: 0.2 | Z9: 0.15 | AA9: 1 | AB9: 1
A10: Region | B10: Council | C10: Code | D10: SPEI-12 drought depth | E10: Aridity (P/PET) | F10: Rainfall variability (CV) | G10: Growing-season failure frequency | H10: Vegetation/biomass anomaly (NDVI z) | I10: Soil moisture | J10: Water levels (% of normal) | K10: Extreme wet days (>50 mm) | L10: Very-heavy days (>100 mm) | M10: River peak above normal | N10: Basin flood records | O10: Recorded flood impact events | P10: Landslide susceptibility | Q10: Triggering rainfall (max 5-day) | R10: Cyclone/strong-wind frequency | S10: Extreme wind speed | T10: Seismic hazard (PGA 475-yr) | U10: Historical seismicity density | V10: Significant wave height (Hs 99th pct) | W10: Extreme onshore wind | X10: Storm-surge frequency | Y10: Shoreline retreat / erosion rate | Z10: Mangrove loss (protective buffer) | AA10: Heat-health days (> 90th pct Tmax) | AB10: Flash density
A11: Arusha | B11: Arusha City | C11: C015
A12: Arusha | B12: Arusha District | C12: C011
A13: Arusha | B13: Karatu District | C13: C013
A14: Arusha | B14: Longido District | C14: C012
A15: Arusha | B15: Meru District | C15: C010
A16: Arusha | B16: Monduli District | C16: C009
A17: Arusha | B17: Ngorongoro District | C17: C014
A18: Dar es Salaam | B18: Dar Es Salaam City | C18: C053
A19: Dar es Salaam | B19: Kigamboni Municipal | C19: C055
A20: Dar es Salaam | B20: Kinondoni Municipal | C20: C052
A21: Dar es Salaam | B21: Temeke Municipal | C21: C054
A22: Dar es Salaam | B22: Ubungo Municipal | C22: C056
... A205: Tanga | B205: Tanga City | C205: C028

Sheet Advanced 0-10
A10: Region | B10: Council | C10: Code | D10: SPEI-12 drought depth | E10: Aridity (P/PET) | F10: Rainfall variability (CV) | G10: Growing-season failure frequency | H10: Vegetation/biomass anomaly (NDVI z) | I10: Soil moisture | J10: Water levels (% of normal) | K10: Extreme wet days (>50 mm) | L10: Very-heavy days (>100 mm) | M10: River peak above normal | N10: Basin flood records | O10: Recorded flood impact events | P10: Landslide susceptibility | Q10: Triggering rainfall (max 5-day) | R10: Cyclone/strong-wind frequency | S10: Extreme wind speed | T10: Seismic hazard (PGA 475-yr) | U10: Historical seismicity density | V10: Significant wave height (Hs 99th pct) | W10: Extreme onshore wind | X10: Storm-surge frequency | Y10: Shoreline retreat / erosion rate | Z10: Mangrove loss (protective buffer) | AA10: Heat-health days (> 90th pct Tmax) | AB10: Flash density
A11: Arusha | B11: Arusha City | C11: C015 | D11: =IF('Advanced Entry'!D11="","",IFERROR(MAX(0,MIN(10,ROUND(IF('Advanced Entry'!D$8="Decrease Risk",10-10*((IF('Advanced Entry'!D$5="Logarithm",LN(0.001+'Advanced Entry'!D11),IF('Advanced Entry'!D$5="Exponential",EXP('Advanced Entry'!D11),'Advanced Entry'!D11)))-'Advanced Entry'!D$6)/('Advanced Entry'!D$7-'Advanced Entry'!D$6),10*((IF('Advanced Entry'!D$5="Logarithm",LN(0.001+'Advanced Entry'!D11),IF('Advanced Entry'!D$5="Exponential",EXP('Advanced Entry'!D11),'Advanced Entry'!D11)))-'Advanced Entry'!D$6)/('Advanced Entry'!D$7-'Advanced Entry'!D$6)),1))),"No data")) | E11: =IF('Advanced Entry'!E11="","",IFERROR(MAX(0,MIN(10,ROUND(IF('Advanced Entry'!E$8="Decrease Risk",10-10*((IF('Advanced Entry'!E$5="Logarithm",LN(0.001+'Advanced Entry'!E11),IF('Advanced Entry'!E$5="Exponential",EXP('Advanced Entry'!E11),'Advanced Entry'!E11)))-'Advanced Entry'!E$6)/('Advanced Entry'!E$7-'Advanced Entry'!E$6),10*((IF('Advanced Entry'!E$5="Logarithm",LN(0.001+'Advanced Entry'!E11),IF('Advanced Entry'!E$5="Exponential",EXP('Advanced Entry'!E11),'Advanced Entry'!E11)))-'Advanced Entry'!E$6)/('Advanced Entry'!E$7-'Advanced Entry'!E$6)),1))),"No data")) | F11: =IF('Advanced Entry'!F11="","",IFERROR(MAX(0,MIN(10,ROUND(IF('Advanced Entry'!F$8="Decrease Risk",10-10*((IF('Advanced Entry'!F$5="Logarithm",LN(0.001+'Advanced Entry'!F11),IF('Advanced Entry'!F$5="Exponential",EXP('Advanced Entry'!F11),'Advanced Entry'!F11)))-'Advanced Entry'!F$6)/('Advanced Entry'!F$7-'Advanced Entry'!F$6),10*((IF('Advanced Entry'!F$5="Logarithm",LN(0.001+'Advanced Entry'!F11),IF('Advanced Entry'!F$5="Exponential",EXP('Advanced Entry'!F11),'Advanced Entry'!F11)))-'Advanced Entry'!F$6)/('Advanced Entry'!F$7-'Advanced Entry'!F$6)),1))),"No data")) | G11: =IF('Advanced Entry'!G11="","",IFERROR(MAX(0,MIN(10,ROUND(IF('Advanced Entry'!G$8="Decrease Risk",10-10*((IF('Advanced Entry'!G$5="Logarithm",LN(0.001+'Advanced Entry'!G11),IF('Advanced Entry'!G$5="Exponential",EXP('Advanced Entry'!G11),'Advanced Entry'!G11)))-'Advanced Entry'!G$6)/('Advanced Entry'!G$7-'Advanced Entry'!G$6),10*((IF('Advanced Entry'!G$5="Logarithm",LN(0.001+'Advanced Entry'!G11),IF('Advanced Entry'!G$5="Exponential",EXP('Advanced Entry'!G11),'Advanced Entry'!G11)))-'Advanced Entry'!G$6)/('Advanced Entry'!G$7-'Advanced Entry'!G$6)),1))),"No data")) | H11: =IF('Advanced Entry'!H11="","",IFERROR(MAX(0,MIN(10,ROUND(IF('Advanced Entry'!H$8="Decrease Risk",10-10*((IF('Advanced Entry'!H$5="Logarithm",LN(0.001+'Advanced Entry'!H11),IF('Advanced Entry'!H$5="Exponential",EXP('Advanced Entry'!H11),'Advanced Entry'!H11)))-'Advanced Entry'!H$6)/('Advanced Entry'!H$7-'Advanced Entry'!H$6),10*((IF('Advanced Entry'!H$5="Logarithm",LN(0.001+'Advanced Entry'!H11),IF('Advanced Entry'!H$5="Exponential",EXP('Advanced Entry'!H11),'Advanced Entry'!H11)))-'Advanced Entry'!H$6)/('Advanced Entry'!H$7-'Advanced Entry'!H$6)),1))),"No data")) | I11: =IF('Advanced Entry'!I11="","",IFERROR(MAX(0,MIN(10,ROUND(IF('Advanced Entry'!I$8="Decrease Risk",10-10*((IF('Advanced Entry'!I$5="Logarithm",LN(0.001+'Advanced Entry'!I11),IF('Advanced Entry'!I$5="Exponential",EXP('Advanced Entry'!I11),'Advanced Entry'!I11)))-'Advanced Entry'!I$6)/('Advanced Entry'!I$7-'Advanced Entry'!I$6),10*((IF('Advanced Entry'!I$5="Logarithm",LN(0.001+'Advanced Entry'!I11),IF('Advanced Entry'!I$5="Exponential",EXP('Advanced Entry'!I11),'Advanced Entry'!I11)))-'Advanced Entry'!I$6)/('Advanced Entry'!I$7-'Advanced Entry'!I$6)),1))),"No data")) | J11: =IF('Advanced Entry'!J11="","",IFERROR(MAX(0,MIN(10,ROUND(IF('Advanced Entry'!J$8="Decrease Risk",10-10*((IF('Advanced Entry'!J$5="Logarithm",LN(0.001+'Advanced Entry'!J11),IF('Advanced Entry'!J$5="Exponential",EXP('Advanced Entry'!J11),'Advanced Entry'!J11)))-'Advanced Entry'!J$6)/('Advanced Entry'!J$7-'Advanced Entry'!J$6),10*((IF('Advanced Entry'!J$5="Logarithm",LN(0.001+'Advanced Entry'!J11),IF('Advanced Entry'!J$5="Exponential",EXP('Advanced Entry'!J11),'Advanced Entry'!J11)))-'Advanced Entry'!J$6)/('Advanced Entry'!J$7-'Advanced Entry'!J$6)),1))),"No data")) | K11: =IF('Advanced Entry'!K11="","",IFERROR(MAX(0,MIN(10,ROUND(IF('Advanced Entry'!K$8="Decrease Risk",10-10*((IF('Advanced Entry'!K$5="Logarithm",LN(0.001+'Advanced Entry'!K11),IF('Advanced Entry'!K$5="Exponential",EXP('Advanced Entry'!K11),'Advanced Entry'!K11)))-'Advanced Entry'!K$6)/('Advanced Entry'!K$7-'Advanced Entry'!K$6),10*((IF('Advanced Entry'!K$5="Logarithm",LN(0.001+'Advanced Entry'!K11),IF('Advanced Entry'!K$5="Exponential",EXP('Advanced Entry'!K11),'Advanced Entry'!K11)))-'Advanced Entry'!K$6)/('Advanced Entry'!K$7-'Advanced Entry'!K$6)),1))),"No data")) | ... AB11: =IF('Advanced Entry'!AB11="","",IFERROR(MAX(0,MIN(10,ROUND(IF('Advanced Entry'!AB$8="Decrease Risk",10-10*((IF('Advanced Entry'!AB$5="Logarithm",LN(0.001+'Advanced Entry'!AB11),IF('Advanced Entry'!AB$5="Exponential",EXP('Advanced Entry'!AB11),'Advanced Entry'!AB11)))-'Advanced Entry'!AB$6)/('Advanced Entry'!AB$7-'Advanced Entry'!AB$6),10*((IF('Advanced Entry'!AB$5="Logarithm",LN(0.001+'Advanced Entry'!AB11),IF('Advanced Entry'!AB$5="Exponential",EXP('Advanced Entry'!AB11),'Advanced Entry'!AB11)))-'Advanced Entry'!AB$6)/('Advanced Entry'!AB$7-'Advanced Entry'!AB$6)),1))),"No data"))
A12: Arusha | B12: Arusha District | C12: C011 | D12: =IF('Advanced Entry'!D12="","",IFERROR(MAX(0,MIN(10,ROUND(IF('Advanced Entry'!D$8="Decrease Risk",10-10*((IF('Advanced Entry'!D$5="Logarithm",LN(0.001+'Advanced Entry'!D12),IF('Advanced Entry'!D$5="Exponential",EXP('Advanced Entry'!D12),'Advanced Entry'!D12)))-'Advanced Entry'!D$6)/('Advanced Entry'!D$7-'Advanced Entry'!D$6),10*((IF('Advanced Entry'!D$5="Logarithm",LN(0.001+'Advanced Entry'!D12),IF('Advanced Entry'!D$5="Exponential",EXP('Advanced Entry'!D12),'Advanced Entry'!D12)))-'Advanced Entry'!D$6)/('Advanced Entry'!D$7-'Advanced Entry'!D$6)),1))),"No data")) | E12: =IF('Advanced Entry'!E12="","",IFERROR(MAX(0,MIN(10,ROUND(IF('Advanced Entry'!E$8="Decrease Risk",10-10*((IF('Advanced Entry'!E$5="Logarithm",LN(0.001+'Advanced Entry'!E12),IF('Advanced Entry'!E$5="Exponential",EXP('Advanced Entry'!E12),'Advanced Entry'!E12)))-'Advanced Entry'!E$6)/('Advanced Entry'!E$7-'Advanced Entry'!E$6),10*((IF('Advanced Entry'!E$5="Logarithm",LN(0.001+'Advanced Entry'!E12),IF('Advanced Entry'!E$5="Exponential",EXP('Advanced Entry'!E12),'Advanced Entry'!E12)))-'Advanced Entry'!E$6)/('Advanced Entry'!E$7-'Advanced Entry'!E$6)),1))),"No data")) | F12: =IF('Advanced Entry'!F12="","",IFERROR(MAX(0,MIN(10,ROUND(IF('Advanced Entry'!F$8="Decrease Risk",10-10*((IF('Advanced Entry'!F$5="Logarithm",LN(0.001+'Advanced Entry'!F12),IF('Advanced Entry'!F$5="Exponential",EXP('Advanced Entry'!F12),'Advanced Entry'!F12)))-'Advanced Entry'!F$6)/('Advanced Entry'!F$7-'Advanced Entry'!F$6),10*((IF('Advanced Entry'!F$5="Logarithm",LN(0.001+'Advanced Entry'!F12),IF('Advanced Entry'!F$5="Exponential",EXP('Advanced Entry'!F12),'Advanced Entry'!F12)))-'Advanced Entry'!F$6)/('Advanced Entry'!F$7-'Advanced Entry'!F$6)),1))),"No data")) | G12: =IF('Advanced Entry'!G12="","",IFERROR(MAX(0,MIN(10,ROUND(IF('Advanced Entry'!G$8="Decrease Risk",10-10*((IF('Advanced Entry'!G$5="Logarithm",LN(0.001+'Advanced Entry'!G12),IF('Advanced Entry'!G$5="Exponential",EXP('Advanced Entry'!G12),'Advanced Entry'!G12)))-'Advanced Entry'!G$6)/('Advanced Entry'!G$7-'Advanced Entry'!G$6),10*((IF('Advanced Entry'!G$5="Logarithm",LN(0.001+'Advanced Entry'!G12),IF('Advanced Entry'!G$5="Exponential",EXP('Advanced Entry'!G12),'Advanced Entry'!G12)))-'Advanced Entry'!G$6)/('Advanced Entry'!G$7-'Advanced Entry'!G$6)),1))),"No data")) | H12: =IF('Advanced Entry'!H12="","",IFERROR(MAX(0,MIN(10,ROUND(IF('Advanced Entry'!H$8="Decrease Risk",10-10*((IF('Advanced Entry'!H$5="Logarithm",LN(0.001+'Advanced Entry'!H12),IF('Advanced Entry'!H$5="Exponential",EXP('Advanced Entry'!H12),'Advanced Entry'!H12)))-'Advanced Entry'!H$6)/('Advanced Entry'!H$7-'Advanced Entry'!H$6),10*((IF('Advanced Entry'!H$5="Logarithm",LN(0.001+'Advanced Entry'!H12),IF('Advanced Entry'!H$5="Exponential",EXP('Advanced Entry'!H12),'Advanced Entry'!H12)))-'Advanced Entry'!H$6)/('Advanced Entry'!H$7-'Advanced Entry'!H$6)),1))),"No data")) | I12: =IF('Advanced Entry'!I12="","",IFERROR(MAX(0,MIN(10,ROUND(IF('Advanced Entry'!I$8="Decrease Risk",10-10*((IF('Advanced Entry'!I$5="Logarithm",LN(0.001+'Advanced Entry'!I12),IF('Advanced Entry'!I$5="Exponential",EXP('Advanced Entry'!I12),'Advanced Entry'!I12)))-'Advanced Entry'!I$6)/('Advanced Entry'!I$7-'Advanced Entry'!I$6),10*((IF('Advanced Entry'!I$5="Logarithm",LN(0.001+'Advanced Entry'!I12),IF('Advanced Entry'!I$5="Exponential",EXP('Advanced Entry'!I12),'Advanced Entry'!I12)))-'Advanced Entry'!I$6)/('Advanced Entry'!I$7-'Advanced Entry'!I$6)),1))),"No data")) | J12: =IF('Advanced Entry'!J12="","",IFERROR(MAX(0,MIN(10,ROUND(IF('Advanced Entry'!J$8="Decrease Risk",10-10*((IF('Advanced Entry'!J$5="Logarithm",LN(0.001+'Advanced Entry'!J12),IF('Advanced Entry'!J$5="Exponential",EXP('Advanced Entry'!J12),'Advanced Entry'!J12)))-'Advanced Entry'!J$6)/('Advanced Entry'!J$7-'Advanced Entry'!J$6),10*((IF('Advanced Entry'!J$5="Logarithm",LN(0.001+'Advanced Entry'!J12),IF('Advanced Entry'!J$5="Exponential",EXP('Advanced Entry'!J12),'Advanced Entry'!J12)))-'Advanced Entry'!J$6)/('Advanced Entry'!J$7-'Advanced Entry'!J$6)),1))),"No data")) | K12: =IF('Advanced Entry'!K12="","",IFERROR(MAX(0,MIN(10,ROUND(IF('Advanced Entry'!K$8="Decrease Risk",10-10*((IF('Advanced Entry'!K$5="Logarithm",LN(0.001+'Advanced Entry'!K12),IF('Advanced Entry'!K$5="Exponential",EXP('Advanced Entry'!K12),'Advanced Entry'!K12)))-'Advanced Entry'!K$6)/('Advanced Entry'!K$7-'Advanced Entry'!K$6),10*((IF('Advanced Entry'!K$5="Logarithm",LN(0.001+'Advanced Entry'!K12),IF('Advanced Entry'!K$5="Exponential",EXP('Advanced Entry'!K12),'Advanced Entry'!K12)))-'Advanced Entry'!K$6)/('Advanced Entry'!K$7-'Advanced Entry'!K$6)),1))),"No data")) | ... AB12: =IF('Advanced Entry'!AB12="","",IFERROR(MAX(0,MIN(10,ROUND(IF('Advanced Entry'!AB$8="Decrease Risk",10-10*((IF('Advanced Entry'!AB$5="Logarithm",LN(0.001+'Advanced Entry'!AB12),IF('Advanced Entry'!AB$5="Exponential",EXP('Advanced Entry'!AB12),'Advanced Entry'!AB12)))-'Advanced Entry'!AB$6)/('Advanced Entry'!AB$7-'Advanced Entry'!AB$6),10*((IF('Advanced Entry'!AB$5="Logarithm",LN(0.001+'Advanced Entry'!AB12),IF('Advanced Entry'!AB$5="Exponential",EXP('Advanced Entry'!AB12),'Advanced Entry'!AB12)))-'Advanced Entry'!AB$6)/('Advanced Entry'!AB$7-'Advanced Entry'!AB$6)),1))),"No data"))
A13: Arusha | B13: Karatu District | C13: C013 | D13: =IF('Advanced Entry'!D13="","",IFERROR(MAX(0,MIN(10,ROUND(IF('Advanced Entry'!D$8="Decrease Risk",10-10*((IF('Advanced Entry'!D$5="Logarithm",LN(0.001+'Advanced Entry'!D13),IF('Advanced Entry'!D$5="Exponential",EXP('Advanced Entry'!D13),'Advanced Entry'!D13)))-'Advanced Entry'!D$6)/('Advanced Entry'!D$7-'Advanced Entry'!D$6),10*((IF('Advanced Entry'!D$5="Logarithm",LN(0.001+'Advanced Entry'!D13),IF('Advanced Entry'!D$5="Exponential",EXP('Advanced Entry'!D13),'Advanced Entry'!D13)))-'Advanced Entry'!D$6)/('Advanced Entry'!D$7-'Advanced Entry'!D$6)),1))),"No data")) | E13: =IF('Advanced Entry'!E13="","",IFERROR(MAX(0,MIN(10,ROUND(IF('Advanced Entry'!E$8="Decrease Risk",10-10*((IF('Advanced Entry'!E$5="Logarithm",LN(0.001+'Advanced Entry'!E13),IF('Advanced Entry'!E$5="Exponential",EXP('Advanced Entry'!E13),'Advanced Entry'!E13)))-'Advanced Entry'!E$6)/('Advanced Entry'!E$7-'Advanced Entry'!E$6),10*((IF('Advanced Entry'!E$5="Logarithm",LN(0.001+'Advanced Entry'!E13),IF('Advanced Entry'!E$5="Exponential",EXP('Advanced Entry'!E13),'Advanced Entry'!E13)))-'Advanced Entry'!E$6)/('Advanced Entry'!E$7-'Advanced Entry'!E$6)),1))),"No data")) | F13: =IF('Advanced Entry'!F13="","",IFERROR(MAX(0,MIN(10,ROUND(IF('Advanced Entry'!F$8="Decrease Risk",10-10*((IF('Advanced Entry'!F$5="Logarithm",LN(0.001+'Advanced Entry'!F13),IF('Advanced Entry'!F$5="Exponential",EXP('Advanced Entry'!F13),'Advanced Entry'!F13)))-'Advanced Entry'!F$6)/('Advanced Entry'!F$7-'Advanced Entry'!F$6),10*((IF('Advanced Entry'!F$5="Logarithm",LN(0.001+'Advanced Entry'!F13),IF('Advanced Entry'!F$5="Exponential",EXP('Advanced Entry'!F13),'Advanced Entry'!F13)))-'Advanced Entry'!F$6)/('Advanced Entry'!F$7-'Advanced Entry'!F$6)),1))),"No data")) | G13: =IF('Advanced Entry'!G13="","",IFERROR(MAX(0,MIN(10,ROUND(IF('Advanced Entry'!G$8="Decrease Risk",10-10*((IF('Advanced Entry'!G$5="Logarithm",LN(0.001+'Advanced Entry'!G13),IF('Advanced Entry'!G$5="Exponential",EXP('Advanced Entry'!G13),'Advanced Entry'!G13)))-'Advanced Entry'!G$6)/('Advanced Entry'!G$7-'Advanced Entry'!G$6),10*((IF('Advanced Entry'!G$5="Logarithm",LN(0.001+'Advanced Entry'!G13),IF('Advanced Entry'!G$5="Exponential",EXP('Advanced Entry'!G13),'Advanced Entry'!G13)))-'Advanced Entry'!G$6)/('Advanced Entry'!G$7-'Advanced Entry'!G$6)),1))),"No data")) | H13: =IF('Advanced Entry'!H13="","",IFERROR(MAX(0,MIN(10,ROUND(IF('Advanced Entry'!H$8="Decrease Risk",10-10*((IF('Advanced Entry'!H$5="Logarithm",LN(0.001+'Advanced Entry'!H13),IF('Advanced Entry'!H$5="Exponential",EXP('Advanced Entry'!H13),'Advanced Entry'!H13)))-'Advanced Entry'!H$6)/('Advanced Entry'!H$7-'Advanced Entry'!H$6),10*((IF('Advanced Entry'!H$5="Logarithm",LN(0.001+'Advanced Entry'!H13),IF('Advanced Entry'!H$5="Exponential",EXP('Advanced Entry'!H13),'Advanced Entry'!H13)))-'Advanced Entry'!H$6)/('Advanced Entry'!H$7-'Advanced Entry'!H$6)),1))),"No data")) | I13: =IF('Advanced Entry'!I13="","",IFERROR(MAX(0,MIN(10,ROUND(IF('Advanced Entry'!I$8="Decrease Risk",10-10*((IF('Advanced Entry'!I$5="Logarithm",LN(0.001+'Advanced Entry'!I13),IF('Advanced Entry'!I$5="Exponential",EXP('Advanced Entry'!I13),'Advanced Entry'!I13)))-'Advanced Entry'!I$6)/('Advanced Entry'!I$7-'Advanced Entry'!I$6),10*((IF('Advanced Entry'!I$5="Logarithm",LN(0.001+'Advanced Entry'!I13),IF('Advanced Entry'!I$5="Exponential",EXP('Advanced Entry'!I13),'Advanced Entry'!I13)))-'Advanced Entry'!I$6)/('Advanced Entry'!I$7-'Advanced Entry'!I$6)),1))),"No data")) | J13: =IF('Advanced Entry'!J13="","",IFERROR(MAX(0,MIN(10,ROUND(IF('Advanced Entry'!J$8="Decrease Risk",10-10*((IF('Advanced Entry'!J$5="Logarithm",LN(0.001+'Advanced Entry'!J13),IF('Advanced Entry'!J$5="Exponential",EXP('Advanced Entry'!J13),'Advanced Entry'!J13)))-'Advanced Entry'!J$6)/('Advanced Entry'!J$7-'Advanced Entry'!J$6),10*((IF('Advanced Entry'!J$5="Logarithm",LN(0.001+'Advanced Entry'!J13),IF('Advanced Entry'!J$5="Exponential",EXP('Advanced Entry'!J13),'Advanced Entry'!J13)))-'Advanced Entry'!J$6)/('Advanced Entry'!J$7-'Advanced Entry'!J$6)),1))),"No data")) | K13: =IF('Advanced Entry'!K13="","",IFERROR(MAX(0,MIN(10,ROUND(IF('Advanced Entry'!K$8="Decrease Risk",10-10*((IF('Advanced Entry'!K$5="Logarithm",LN(0.001+'Advanced Entry'!K13),IF('Advanced Entry'!K$5="Exponential",EXP('Advanced Entry'!K13),'Advanced Entry'!K13)))-'Advanced Entry'!K$6)/('Advanced Entry'!K$7-'Advanced Entry'!K$6),10*((IF('Advanced Entry'!K$5="Logarithm",LN(0.001+'Advanced Entry'!K13),IF('Advanced Entry'!K$5="Exponential",EXP('Advanced Entry'!K13),'Advanced Entry'!K13)))-'Advanced Entry'!K$6)/('Advanced Entry'!K$7-'Advanced Entry'!K$6)),1))),"No data")) | ... AB13: =IF('Advanced Entry'!AB13="","",IFERROR(MAX(0,MIN(10,ROUND(IF('Advanced Entry'!AB$8="Decrease Risk",10-10*((IF('Advanced Entry'!AB$5="Logarithm",LN(0.001+'Advanced Entry'!AB13),IF('Advanced Entry'!AB$5="Exponential",EXP('Advanced Entry'!AB13),'Advanced Entry'!AB13)))-'Advanced Entry'!AB$6)/('Advanced Entry'!AB$7-'Advanced Entry'!AB$6),10*((IF('Advanced Entry'!AB$5="Logarithm",LN(0.001+'Advanced Entry'!AB13),IF('Advanced Entry'!AB$5="Exponential",EXP('Advanced Entry'!AB13),'Advanced Entry'!AB13)))-'Advanced Entry'!AB$6)/('Advanced Entry'!AB$7-'Advanced Entry'!AB$6)),1))),"No data"))
A14: Arusha | B14: Longido District | C14: C012 | D14: =IF('Advanced Entry'!D14="","",IFERROR(MAX(0,MIN(10,ROUND(IF('Advanced Entry'!D$8="Decrease Risk",10-10*((IF('Advanced Entry'!D$5="Logarithm",LN(0.001+'Advanced Entry'!D14),IF('Advanced Entry'!D$5="Exponential",EXP('Advanced Entry'!D14),'Advanced Entry'!D14)))-'Advanced Entry'!D$6)/('Advanced Entry'!D$7-'Advanced Entry'!D$6),10*((IF('Advanced Entry'!D$5="Logarithm",LN(0.001+'Advanced Entry'!D14),IF('Advanced Entry'!D$5="Exponential",EXP('Advanced Entry'!D14),'Advanced Entry'!D14)))-'Advanced Entry'!D$6)/('Advanced Entry'!D$7-'Advanced Entry'!D$6)),1))),"No data")) | E14: =IF('Advanced Entry'!E14="","",IFERROR(MAX(0,MIN(10,ROUND(IF('Advanced Entry'!E$8="Decrease Risk",10-10*((IF('Advanced Entry'!E$5="Logarithm",LN(0.001+'Advanced Entry'!E14),IF('Advanced Entry'!E$5="Exponential",EXP('Advanced Entry'!E14),'Advanced Entry'!E14)))-'Advanced Entry'!E$6)/('Advanced Entry'!E$7-'Advanced Entry'!E$6),10*((IF('Advanced Entry'!E$5="Logarithm",LN(0.001+'Advanced Entry'!E14),IF('Advanced Entry'!E$5="Exponential",EXP('Advanced Entry'!E14),'Advanced Entry'!E14)))-'Advanced Entry'!E$6)/('Advanced Entry'!E$7-'Advanced Entry'!E$6)),1))),"No data")) | F14: =IF('Advanced Entry'!F14="","",IFERROR(MAX(0,MIN(10,ROUND(IF('Advanced Entry'!F$8="Decrease Risk",10-10*((IF('Advanced Entry'!F$5="Logarithm",LN(0.001+'Advanced Entry'!F14),IF('Advanced Entry'!F$5="Exponential",EXP('Advanced Entry'!F14),'Advanced Entry'!F14)))-'Advanced Entry'!F$6)/('Advanced Entry'!F$7-'Advanced Entry'!F$6),10*((IF('Advanced Entry'!F$5="Logarithm",LN(0.001+'Advanced Entry'!F14),IF('Advanced Entry'!F$5="Exponential",EXP('Advanced Entry'!F14),'Advanced Entry'!F14)))-'Advanced Entry'!F$6)/('Advanced Entry'!F$7-'Advanced Entry'!F$6)),1))),"No data")) | G14: =IF('Advanced Entry'!G14="","",IFERROR(MAX(0,MIN(10,ROUND(IF('Advanced Entry'!G$8="Decrease Risk",10-10*((IF('Advanced Entry'!G$5="Logarithm",LN(0.001+'Advanced Entry'!G14),IF('Advanced Entry'!G$5="Exponential",EXP('Advanced Entry'!G14),'Advanced Entry'!G14)))-'Advanced Entry'!G$6)/('Advanced Entry'!G$7-'Advanced Entry'!G$6),10*((IF('Advanced Entry'!G$5="Logarithm",LN(0.001+'Advanced Entry'!G14),IF('Advanced Entry'!G$5="Exponential",EXP('Advanced Entry'!G14),'Advanced Entry'!G14)))-'Advanced Entry'!G$6)/('Advanced Entry'!G$7-'Advanced Entry'!G$6)),1))),"No data")) | H14: =IF('Advanced Entry'!H14="","",IFERROR(MAX(0,MIN(10,ROUND(IF('Advanced Entry'!H$8="Decrease Risk",10-10*((IF('Advanced Entry'!H$5="Logarithm",LN(0.001+'Advanced Entry'!H14),IF('Advanced Entry'!H$5="Exponential",EXP('Advanced Entry'!H14),'Advanced Entry'!H14)))-'Advanced Entry'!H$6)/('Advanced Entry'!H$7-'Advanced Entry'!H$6),10*((IF('Advanced Entry'!H$5="Logarithm",LN(0.001+'Advanced Entry'!H14),IF('Advanced Entry'!H$5="Exponential",EXP('Advanced Entry'!H14),'Advanced Entry'!H14)))-'Advanced Entry'!H$6)/('Advanced Entry'!H$7-'Advanced Entry'!H$6)),1))),"No data")) | I14: =IF('Advanced Entry'!I14="","",IFERROR(MAX(0,MIN(10,ROUND(IF('Advanced Entry'!I$8="Decrease Risk",10-10*((IF('Advanced Entry'!I$5="Logarithm",LN(0.001+'Advanced Entry'!I14),IF('Advanced Entry'!I$5="Exponential",EXP('Advanced Entry'!I14),'Advanced Entry'!I14)))-'Advanced Entry'!I$6)/('Advanced Entry'!I$7-'Advanced Entry'!I$6),10*((IF('Advanced Entry'!I$5="Logarithm",LN(0.001+'Advanced Entry'!I14),IF('Advanced Entry'!I$5="Exponential",EXP('Advanced Entry'!I14),'Advanced Entry'!I14)))-'Advanced Entry'!I$6)/('Advanced Entry'!I$7-'Advanced Entry'!I$6)),1))),"No data")) | J14: =IF('Advanced Entry'!J14="","",IFERROR(MAX(0,MIN(10,ROUND(IF('Advanced Entry'!J$8="Decrease Risk",10-10*((IF('Advanced Entry'!J$5="Logarithm",LN(0.001+'Advanced Entry'!J14),IF('Advanced Entry'!J$5="Exponential",EXP('Advanced Entry'!J14),'Advanced Entry'!J14)))-'Advanced Entry'!J$6)/('Advanced Entry'!J$7-'Advanced Entry'!J$6),10*((IF('Advanced Entry'!J$5="Logarithm",LN(0.001+'Advanced Entry'!J14),IF('Advanced Entry'!J$5="Exponential",EXP('Advanced Entry'!J14),'Advanced Entry'!J14)))-'Advanced Entry'!J$6)/('Advanced Entry'!J$7-'Advanced Entry'!J$6)),1))),"No data")) | K14: =IF('Advanced Entry'!K14="","",IFERROR(MAX(0,MIN(10,ROUND(IF('Advanced Entry'!K$8="Decrease Risk",10-10*((IF('Advanced Entry'!K$5="Logarithm",LN(0.001+'Advanced Entry'!K14),IF('Advanced Entry'!K$5="Exponential",EXP('Advanced Entry'!K14),'Advanced Entry'!K14)))-'Advanced Entry'!K$6)/('Advanced Entry'!K$7-'Advanced Entry'!K$6),10*((IF('Advanced Entry'!K$5="Logarithm",LN(0.001+'Advanced Entry'!K14),IF('Advanced Entry'!K$5="Exponential",EXP('Advanced Entry'!K14),'Advanced Entry'!K14)))-'Advanced Entry'!K$6)/('Advanced Entry'!K$7-'Advanced Entry'!K$6)),1))),"No data")) | ... AB14: =IF('Advanced Entry'!AB14="","",IFERROR(MAX(0,MIN(10,ROUND(IF('Advanced Entry'!AB$8="Decrease Risk",10-10*((IF('Advanced Entry'!AB$5="Logarithm",LN(0.001+'Advanced Entry'!AB14),IF('Advanced Entry'!AB$5="Exponential",EXP('Advanced Entry'!AB14),'Advanced Entry'!AB14)))-'Advanced Entry'!AB$6)/('Advanced Entry'!AB$7-'Advanced Entry'!AB$6),10*((IF('Advanced Entry'!AB$5="Logarithm",LN(0.001+'Advanced Entry'!AB14),IF('Advanced Entry'!AB$5="Exponential",EXP('Advanced Entry'!AB14),'Advanced Entry'!AB14)))-'Advanced Entry'!AB$6)/('Advanced Entry'!AB$7-'Advanced Entry'!AB$6)),1))),"No data"))
A15: Arusha | B15: Meru District | C15: C010 | D15: =IF('Advanced Entry'!D15="","",IFERROR(MAX(0,MIN(10,ROUND(IF('Advanced Entry'!D$8="Decrease Risk",10-10*((IF('Advanced Entry'!D$5="Logarithm",LN(0.001+'Advanced Entry'!D15),IF('Advanced Entry'!D$5="Exponential",EXP('Advanced Entry'!D15),'Advanced Entry'!D15)))-'Advanced Entry'!D$6)/('Advanced Entry'!D$7-'Advanced Entry'!D$6),10*((IF('Advanced Entry'!D$5="Logarithm",LN(0.001+'Advanced Entry'!D15),IF('Advanced Entry'!D$5="Exponential",EXP('Advanced Entry'!D15),'Advanced Entry'!D15)))-'Advanced Entry'!D$6)/('Advanced Entry'!D$7-'Advanced Entry'!D$6)),1))),"No data")) | E15: =IF('Advanced Entry'!E15="","",IFERROR(MAX(0,MIN(10,ROUND(IF('Advanced Entry'!E$8="Decrease Risk",10-10*((IF('Advanced Entry'!E$5="Logarithm",LN(0.001+'Advanced Entry'!E15),IF('Advanced Entry'!E$5="Exponential",EXP('Advanced Entry'!E15),'Advanced Entry'!E15)))-'Advanced Entry'!E$6)/('Advanced Entry'!E$7-'Advanced Entry'!E$6),10*((IF('Advanced Entry'!E$5="Logarithm",LN(0.001+'Advanced Entry'!E15),IF('Advanced Entry'!E$5="Exponential",EXP('Advanced Entry'!E15),'Advanced Entry'!E15)))-'Advanced Entry'!E$6)/('Advanced Entry'!E$7-'Advanced Entry'!E$6)),1))),"No data")) | F15: =IF('Advanced Entry'!F15="","",IFERROR(MAX(0,MIN(10,ROUND(IF('Advanced Entry'!F$8="Decrease Risk",10-10*((IF('Advanced Entry'!F$5="Logarithm",LN(0.001+'Advanced Entry'!F15),IF('Advanced Entry'!F$5="Exponential",EXP('Advanced Entry'!F15),'Advanced Entry'!F15)))-'Advanced Entry'!F$6)/('Advanced Entry'!F$7-'Advanced Entry'!F$6),10*((IF('Advanced Entry'!F$5="Logarithm",LN(0.001+'Advanced Entry'!F15),IF('Advanced Entry'!F$5="Exponential",EXP('Advanced Entry'!F15),'Advanced Entry'!F15)))-'Advanced Entry'!F$6)/('Advanced Entry'!F$7-'Advanced Entry'!F$6)),1))),"No data")) | G15: =IF('Advanced Entry'!G15="","",IFERROR(MAX(0,MIN(10,ROUND(IF('Advanced Entry'!G$8="Decrease Risk",10-10*((IF('Advanced Entry'!G$5="Logarithm",LN(0.001+'Advanced Entry'!G15),IF('Advanced Entry'!G$5="Exponential",EXP('Advanced Entry'!G15),'Advanced Entry'!G15)))-'Advanced Entry'!G$6)/('Advanced Entry'!G$7-'Advanced Entry'!G$6),10*((IF('Advanced Entry'!G$5="Logarithm",LN(0.001+'Advanced Entry'!G15),IF('Advanced Entry'!G$5="Exponential",EXP('Advanced Entry'!G15),'Advanced Entry'!G15)))-'Advanced Entry'!G$6)/('Advanced Entry'!G$7-'Advanced Entry'!G$6)),1))),"No data")) | H15: =IF('Advanced Entry'!H15="","",IFERROR(MAX(0,MIN(10,ROUND(IF('Advanced Entry'!H$8="Decrease Risk",10-10*((IF('Advanced Entry'!H$5="Logarithm",LN(0.001+'Advanced Entry'!H15),IF('Advanced Entry'!H$5="Exponential",EXP('Advanced Entry'!H15),'Advanced Entry'!H15)))-'Advanced Entry'!H$6)/('Advanced Entry'!H$7-'Advanced Entry'!H$6),10*((IF('Advanced Entry'!H$5="Logarithm",LN(0.001+'Advanced Entry'!H15),IF('Advanced Entry'!H$5="Exponential",EXP('Advanced Entry'!H15),'Advanced Entry'!H15)))-'Advanced Entry'!H$6)/('Advanced Entry'!H$7-'Advanced Entry'!H$6)),1))),"No data")) | I15: =IF('Advanced Entry'!I15="","",IFERROR(MAX(0,MIN(10,ROUND(IF('Advanced Entry'!I$8="Decrease Risk",10-10*((IF('Advanced Entry'!I$5="Logarithm",LN(0.001+'Advanced Entry'!I15),IF('Advanced Entry'!I$5="Exponential",EXP('Advanced Entry'!I15),'Advanced Entry'!I15)))-'Advanced Entry'!I$6)/('Advanced Entry'!I$7-'Advanced Entry'!I$6),10*((IF('Advanced Entry'!I$5="Logarithm",LN(0.001+'Advanced Entry'!I15),IF('Advanced Entry'!I$5="Exponential",EXP('Advanced Entry'!I15),'Advanced Entry'!I15)))-'Advanced Entry'!I$6)/('Advanced Entry'!I$7-'Advanced Entry'!I$6)),1))),"No data")) | J15: =IF('Advanced Entry'!J15="","",IFERROR(MAX(0,MIN(10,ROUND(IF('Advanced Entry'!J$8="Decrease Risk",10-10*((IF('Advanced Entry'!J$5="Logarithm",LN(0.001+'Advanced Entry'!J15),IF('Advanced Entry'!J$5="Exponential",EXP('Advanced Entry'!J15),'Advanced Entry'!J15)))-'Advanced Entry'!J$6)/('Advanced Entry'!J$7-'Advanced Entry'!J$6),10*((IF('Advanced Entry'!J$5="Logarithm",LN(0.001+'Advanced Entry'!J15),IF('Advanced Entry'!J$5="Exponential",EXP('Advanced Entry'!J15),'Advanced Entry'!J15)))-'Advanced Entry'!J$6)/('Advanced Entry'!J$7-'Advanced Entry'!J$6)),1))),"No data")) | K15: =IF('Advanced Entry'!K15="","",IFERROR(MAX(0,MIN(10,ROUND(IF('Advanced Entry'!K$8="Decrease Risk",10-10*((IF('Advanced Entry'!K$5="Logarithm",LN(0.001+'Advanced Entry'!K15),IF('Advanced Entry'!K$5="Exponential",EXP('Advanced Entry'!K15),'Advanced Entry'!K15)))-'Advanced Entry'!K$6)/('Advanced Entry'!K$7-'Advanced Entry'!K$6),10*((IF('Advanced Entry'!K$5="Logarithm",LN(0.001+'Advanced Entry'!K15),IF('Advanced Entry'!K$5="Exponential",EXP('Advanced Entry'!K15),'Advanced Entry'!K15)))-'Advanced Entry'!K$6)/('Advanced Entry'!K$7-'Advanced Entry'!K$6)),1))),"No data")) | ... AB15: =IF('Advanced Entry'!AB15="","",IFERROR(MAX(0,MIN(10,ROUND(IF('Advanced Entry'!AB$8="Decrease Risk",10-10*((IF('Advanced Entry'!AB$5="Logarithm",LN(0.001+'Advanced Entry'!AB15),IF('Advanced Entry'!AB$5="Exponential",EXP('Advanced Entry'!AB15),'Advanced Entry'!AB15)))-'Advanced Entry'!AB$6)/('Advanced Entry'!AB$7-'Advanced Entry'!AB$6),10*((IF('Advanced Entry'!AB$5="Logarithm",LN(0.001+'Advanced Entry'!AB15),IF('Advanced Entry'!AB$5="Exponential",EXP('Advanced Entry'!AB15),'Advanced Entry'!AB15)))-'Advanced Entry'!AB$6)/('Advanced Entry'!AB$7-'Advanced Entry'!AB$6)),1))),"No data"))
A16: Arusha | B16: Monduli District | C16: C009 | D16: =IF('Advanced Entry'!D16="","",IFERROR(MAX(0,MIN(10,ROUND(IF('Advanced Entry'!D$8="Decrease Risk",10-10*((IF('Advanced Entry'!D$5="Logarithm",LN(0.001+'Advanced Entry'!D16),IF('Advanced Entry'!D$5="Exponential",EXP('Advanced Entry'!D16),'Advanced Entry'!D16)))-'Advanced Entry'!D$6)/('Advanced Entry'!D$7-'Advanced Entry'!D$6),10*((IF('Advanced Entry'!D$5="Logarithm",LN(0.001+'Advanced Entry'!D16),IF('Advanced Entry'!D$5="Exponential",EXP('Advanced Entry'!D16),'Advanced Entry'!D16)))-'Advanced Entry'!D$6)/('Advanced Entry'!D$7-'Advanced Entry'!D$6)),1))),"No data")) | E16: =IF('Advanced Entry'!E16="","",IFERROR(MAX(0,MIN(10,ROUND(IF('Advanced Entry'!E$8="Decrease Risk",10-10*((IF('Advanced Entry'!E$5="Logarithm",LN(0.001+'Advanced Entry'!E16),IF('Advanced Entry'!E$5="Exponential",EXP('Advanced Entry'!E16),'Advanced Entry'!E16)))-'Advanced Entry'!E$6)/('Advanced Entry'!E$7-'Advanced Entry'!E$6),10*((IF('Advanced Entry'!E$5="Logarithm",LN(0.001+'Advanced Entry'!E16),IF('Advanced Entry'!E$5="Exponential",EXP('Advanced Entry'!E16),'Advanced Entry'!E16)))-'Advanced Entry'!E$6)/('Advanced Entry'!E$7-'Advanced Entry'!E$6)),1))),"No data")) | F16: =IF('Advanced Entry'!F16="","",IFERROR(MAX(0,MIN(10,ROUND(IF('Advanced Entry'!F$8="Decrease Risk",10-10*((IF('Advanced Entry'!F$5="Logarithm",LN(0.001+'Advanced Entry'!F16),IF('Advanced Entry'!F$5="Exponential",EXP('Advanced Entry'!F16),'Advanced Entry'!F16)))-'Advanced Entry'!F$6)/('Advanced Entry'!F$7-'Advanced Entry'!F$6),10*((IF('Advanced Entry'!F$5="Logarithm",LN(0.001+'Advanced Entry'!F16),IF('Advanced Entry'!F$5="Exponential",EXP('Advanced Entry'!F16),'Advanced Entry'!F16)))-'Advanced Entry'!F$6)/('Advanced Entry'!F$7-'Advanced Entry'!F$6)),1))),"No data")) | G16: =IF('Advanced Entry'!G16="","",IFERROR(MAX(0,MIN(10,ROUND(IF('Advanced Entry'!G$8="Decrease Risk",10-10*((IF('Advanced Entry'!G$5="Logarithm",LN(0.001+'Advanced Entry'!G16),IF('Advanced Entry'!G$5="Exponential",EXP('Advanced Entry'!G16),'Advanced Entry'!G16)))-'Advanced Entry'!G$6)/('Advanced Entry'!G$7-'Advanced Entry'!G$6),10*((IF('Advanced Entry'!G$5="Logarithm",LN(0.001+'Advanced Entry'!G16),IF('Advanced Entry'!G$5="Exponential",EXP('Advanced Entry'!G16),'Advanced Entry'!G16)))-'Advanced Entry'!G$6)/('Advanced Entry'!G$7-'Advanced Entry'!G$6)),1))),"No data")) | H16: =IF('Advanced Entry'!H16="","",IFERROR(MAX(0,MIN(10,ROUND(IF('Advanced Entry'!H$8="Decrease Risk",10-10*((IF('Advanced Entry'!H$5="Logarithm",LN(0.001+'Advanced Entry'!H16),IF('Advanced Entry'!H$5="Exponential",EXP('Advanced Entry'!H16),'Advanced Entry'!H16)))-'Advanced Entry'!H$6)/('Advanced Entry'!H$7-'Advanced Entry'!H$6),10*((IF('Advanced Entry'!H$5="Logarithm",LN(0.001+'Advanced Entry'!H16),IF('Advanced Entry'!H$5="Exponential",EXP('Advanced Entry'!H16),'Advanced Entry'!H16)))-'Advanced Entry'!H$6)/('Advanced Entry'!H$7-'Advanced Entry'!H$6)),1))),"No data")) | I16: =IF('Advanced Entry'!I16="","",IFERROR(MAX(0,MIN(10,ROUND(IF('Advanced Entry'!I$8="Decrease Risk",10-10*((IF('Advanced Entry'!I$5="Logarithm",LN(0.001+'Advanced Entry'!I16),IF('Advanced Entry'!I$5="Exponential",EXP('Advanced Entry'!I16),'Advanced Entry'!I16)))-'Advanced Entry'!I$6)/('Advanced Entry'!I$7-'Advanced Entry'!I$6),10*((IF('Advanced Entry'!I$5="Logarithm",LN(0.001+'Advanced Entry'!I16),IF('Advanced Entry'!I$5="Exponential",EXP('Advanced Entry'!I16),'Advanced Entry'!I16)))-'Advanced Entry'!I$6)/('Advanced Entry'!I$7-'Advanced Entry'!I$6)),1))),"No data")) | J16: =IF('Advanced Entry'!J16="","",IFERROR(MAX(0,MIN(10,ROUND(IF('Advanced Entry'!J$8="Decrease Risk",10-10*((IF('Advanced Entry'!J$5="Logarithm",LN(0.001+'Advanced Entry'!J16),IF('Advanced Entry'!J$5="Exponential",EXP('Advanced Entry'!J16),'Advanced Entry'!J16)))-'Advanced Entry'!J$6)/('Advanced Entry'!J$7-'Advanced Entry'!J$6),10*((IF('Advanced Entry'!J$5="Logarithm",LN(0.001+'Advanced Entry'!J16),IF('Advanced Entry'!J$5="Exponential",EXP('Advanced Entry'!J16),'Advanced Entry'!J16)))-'Advanced Entry'!J$6)/('Advanced Entry'!J$7-'Advanced Entry'!J$6)),1))),"No data")) | K16: =IF('Advanced Entry'!K16="","",IFERROR(MAX(0,MIN(10,ROUND(IF('Advanced Entry'!K$8="Decrease Risk",10-10*((IF('Advanced Entry'!K$5="Logarithm",LN(0.001+'Advanced Entry'!K16),IF('Advanced Entry'!K$5="Exponential",EXP('Advanced Entry'!K16),'Advanced Entry'!K16)))-'Advanced Entry'!K$6)/('Advanced Entry'!K$7-'Advanced Entry'!K$6),10*((IF('Advanced Entry'!K$5="Logarithm",LN(0.001+'Advanced Entry'!K16),IF('Advanced Entry'!K$5="Exponential",EXP('Advanced Entry'!K16),'Advanced Entry'!K16)))-'Advanced Entry'!K$6)/('Advanced Entry'!K$7-'Advanced Entry'!K$6)),1))),"No data")) | ... AB16: =IF('Advanced Entry'!AB16="","",IFERROR(MAX(0,MIN(10,ROUND(IF('Advanced Entry'!AB$8="Decrease Risk",10-10*((IF('Advanced Entry'!AB$5="Logarithm",LN(0.001+'Advanced Entry'!AB16),IF('Advanced Entry'!AB$5="Exponential",EXP('Advanced Entry'!AB16),'Advanced Entry'!AB16)))-'Advanced Entry'!AB$6)/('Advanced Entry'!AB$7-'Advanced Entry'!AB$6),10*((IF('Advanced Entry'!AB$5="Logarithm",LN(0.001+'Advanced Entry'!AB16),IF('Advanced Entry'!AB$5="Exponential",EXP('Advanced Entry'!AB16),'Advanced Entry'!AB16)))-'Advanced Entry'!AB$6)/('Advanced Entry'!AB$7-'Advanced Entry'!AB$6)),1))),"No data"))
A17: Arusha | B17: Ngorongoro District | C17: C014 | D17: =IF('Advanced Entry'!D17="","",IFERROR(MAX(0,MIN(10,ROUND(IF('Advanced Entry'!D$8="Decrease Risk",10-10*((IF('Advanced Entry'!D$5="Logarithm",LN(0.001+'Advanced Entry'!D17),IF('Advanced Entry'!D$5="Exponential",EXP('Advanced Entry'!D17),'Advanced Entry'!D17)))-'Advanced Entry'!D$6)/('Advanced Entry'!D$7-'Advanced Entry'!D$6),10*((IF('Advanced Entry'!D$5="Logarithm",LN(0.001+'Advanced Entry'!D17),IF('Advanced Entry'!D$5="Exponential",EXP('Advanced Entry'!D17),'Advanced Entry'!D17)))-'Advanced Entry'!D$6)/('Advanced Entry'!D$7-'Advanced Entry'!D$6)),1))),"No data")) | E17: =IF('Advanced Entry'!E17="","",IFERROR(MAX(0,MIN(10,ROUND(IF('Advanced Entry'!E$8="Decrease Risk",10-10*((IF('Advanced Entry'!E$5="Logarithm",LN(0.001+'Advanced Entry'!E17),IF('Advanced Entry'!E$5="Exponential",EXP('Advanced Entry'!E17),'Advanced Entry'!E17)))-'Advanced Entry'!E$6)/('Advanced Entry'!E$7-'Advanced Entry'!E$6),10*((IF('Advanced Entry'!E$5="Logarithm",LN(0.001+'Advanced Entry'!E17),IF('Advanced Entry'!E$5="Exponential",EXP('Advanced Entry'!E17),'Advanced Entry'!E17)))-'Advanced Entry'!E$6)/('Advanced Entry'!E$7-'Advanced Entry'!E$6)),1))),"No data")) | F17: =IF('Advanced Entry'!F17="","",IFERROR(MAX(0,MIN(10,ROUND(IF('Advanced Entry'!F$8="Decrease Risk",10-10*((IF('Advanced Entry'!F$5="Logarithm",LN(0.001+'Advanced Entry'!F17),IF('Advanced Entry'!F$5="Exponential",EXP('Advanced Entry'!F17),'Advanced Entry'!F17)))-'Advanced Entry'!F$6)/('Advanced Entry'!F$7-'Advanced Entry'!F$6),10*((IF('Advanced Entry'!F$5="Logarithm",LN(0.001+'Advanced Entry'!F17),IF('Advanced Entry'!F$5="Exponential",EXP('Advanced Entry'!F17),'Advanced Entry'!F17)))-'Advanced Entry'!F$6)/('Advanced Entry'!F$7-'Advanced Entry'!F$6)),1))),"No data")) | G17: =IF('Advanced Entry'!G17="","",IFERROR(MAX(0,MIN(10,ROUND(IF('Advanced Entry'!G$8="Decrease Risk",10-10*((IF('Advanced Entry'!G$5="Logarithm",LN(0.001+'Advanced Entry'!G17),IF('Advanced Entry'!G$5="Exponential",EXP('Advanced Entry'!G17),'Advanced Entry'!G17)))-'Advanced Entry'!G$6)/('Advanced Entry'!G$7-'Advanced Entry'!G$6),10*((IF('Advanced Entry'!G$5="Logarithm",LN(0.001+'Advanced Entry'!G17),IF('Advanced Entry'!G$5="Exponential",EXP('Advanced Entry'!G17),'Advanced Entry'!G17)))-'Advanced Entry'!G$6)/('Advanced Entry'!G$7-'Advanced Entry'!G$6)),1))),"No data")) | H17: =IF('Advanced Entry'!H17="","",IFERROR(MAX(0,MIN(10,ROUND(IF('Advanced Entry'!H$8="Decrease Risk",10-10*((IF('Advanced Entry'!H$5="Logarithm",LN(0.001+'Advanced Entry'!H17),IF('Advanced Entry'!H$5="Exponential",EXP('Advanced Entry'!H17),'Advanced Entry'!H17)))-'Advanced Entry'!H$6)/('Advanced Entry'!H$7-'Advanced Entry'!H$6),10*((IF('Advanced Entry'!H$5="Logarithm",LN(0.001+'Advanced Entry'!H17),IF('Advanced Entry'!H$5="Exponential",EXP('Advanced Entry'!H17),'Advanced Entry'!H17)))-'Advanced Entry'!H$6)/('Advanced Entry'!H$7-'Advanced Entry'!H$6)),1))),"No data")) | I17: =IF('Advanced Entry'!I17="","",IFERROR(MAX(0,MIN(10,ROUND(IF('Advanced Entry'!I$8="Decrease Risk",10-10*((IF('Advanced Entry'!I$5="Logarithm",LN(0.001+'Advanced Entry'!I17),IF('Advanced Entry'!I$5="Exponential",EXP('Advanced Entry'!I17),'Advanced Entry'!I17)))-'Advanced Entry'!I$6)/('Advanced Entry'!I$7-'Advanced Entry'!I$6),10*((IF('Advanced Entry'!I$5="Logarithm",LN(0.001+'Advanced Entry'!I17),IF('Advanced Entry'!I$5="Exponential",EXP('Advanced Entry'!I17),'Advanced Entry'!I17)))-'Advanced Entry'!I$6)/('Advanced Entry'!I$7-'Advanced Entry'!I$6)),1))),"No data")) | J17: =IF('Advanced Entry'!J17="","",IFERROR(MAX(0,MIN(10,ROUND(IF('Advanced Entry'!J$8="Decrease Risk",10-10*((IF('Advanced Entry'!J$5="Logarithm",LN(0.001+'Advanced Entry'!J17),IF('Advanced Entry'!J$5="Exponential",EXP('Advanced Entry'!J17),'Advanced Entry'!J17)))-'Advanced Entry'!J$6)/('Advanced Entry'!J$7-'Advanced Entry'!J$6),10*((IF('Advanced Entry'!J$5="Logarithm",LN(0.001+'Advanced Entry'!J17),IF('Advanced Entry'!J$5="Exponential",EXP('Advanced Entry'!J17),'Advanced Entry'!J17)))-'Advanced Entry'!J$6)/('Advanced Entry'!J$7-'Advanced Entry'!J$6)),1))),"No data")) | K17: =IF('Advanced Entry'!K17="","",IFERROR(MAX(0,MIN(10,ROUND(IF('Advanced Entry'!K$8="Decrease Risk",10-10*((IF('Advanced Entry'!K$5="Logarithm",LN(0.001+'Advanced Entry'!K17),IF('Advanced Entry'!K$5="Exponential",EXP('Advanced Entry'!K17),'Advanced Entry'!K17)))-'Advanced Entry'!K$6)/('Advanced Entry'!K$7-'Advanced Entry'!K$6),10*((IF('Advanced Entry'!K$5="Logarithm",LN(0.001+'Advanced Entry'!K17),IF('Advanced Entry'!K$5="Exponential",EXP('Advanced Entry'!K17),'Advanced Entry'!K17)))-'Advanced Entry'!K$6)/('Advanced Entry'!K$7-'Advanced Entry'!K$6)),1))),"No data")) | ... AB17: =IF('Advanced Entry'!AB17="","",IFERROR(MAX(0,MIN(10,ROUND(IF('Advanced Entry'!AB$8="Decrease Risk",10-10*((IF('Advanced Entry'!AB$5="Logarithm",LN(0.001+'Advanced Entry'!AB17),IF('Advanced Entry'!AB$5="Exponential",EXP('Advanced Entry'!AB17),'Advanced Entry'!AB17)))-'Advanced Entry'!AB$6)/('Advanced Entry'!AB$7-'Advanced Entry'!AB$6),10*((IF('Advanced Entry'!AB$5="Logarithm",LN(0.001+'Advanced Entry'!AB17),IF('Advanced Entry'!AB$5="Exponential",EXP('Advanced Entry'!AB17),'Advanced Entry'!AB17)))-'Advanced Entry'!AB$6)/('Advanced Entry'!AB$7-'Advanced Entry'!AB$6)),1))),"No data"))
A18: Dar es Salaam | B18: Dar Es Salaam City | C18: C053 | D18: =IF('Advanced Entry'!D18="","",IFERROR(MAX(0,MIN(10,ROUND(IF('Advanced Entry'!D$8="Decrease Risk",10-10*((IF('Advanced Entry'!D$5="Logarithm",LN(0.001+'Advanced Entry'!D18),IF('Advanced Entry'!D$5="Exponential",EXP('Advanced Entry'!D18),'Advanced Entry'!D18)))-'Advanced Entry'!D$6)/('Advanced Entry'!D$7-'Advanced Entry'!D$6),10*((IF('Advanced Entry'!D$5="Logarithm",LN(0.001+'Advanced Entry'!D18),IF('Advanced Entry'!D$5="Exponential",EXP('Advanced Entry'!D18),'Advanced Entry'!D18)))-'Advanced Entry'!D$6)/('Advanced Entry'!D$7-'Advanced Entry'!D$6)),1))),"No data")) | E18: =IF('Advanced Entry'!E18="","",IFERROR(MAX(0,MIN(10,ROUND(IF('Advanced Entry'!E$8="Decrease Risk",10-10*((IF('Advanced Entry'!E$5="Logarithm",LN(0.001+'Advanced Entry'!E18),IF('Advanced Entry'!E$5="Exponential",EXP('Advanced Entry'!E18),'Advanced Entry'!E18)))-'Advanced Entry'!E$6)/('Advanced Entry'!E$7-'Advanced Entry'!E$6),10*((IF('Advanced Entry'!E$5="Logarithm",LN(0.001+'Advanced Entry'!E18),IF('Advanced Entry'!E$5="Exponential",EXP('Advanced Entry'!E18),'Advanced Entry'!E18)))-'Advanced Entry'!E$6)/('Advanced Entry'!E$7-'Advanced Entry'!E$6)),1))),"No data")) | F18: =IF('Advanced Entry'!F18="","",IFERROR(MAX(0,MIN(10,ROUND(IF('Advanced Entry'!F$8="Decrease Risk",10-10*((IF('Advanced Entry'!F$5="Logarithm",LN(0.001+'Advanced Entry'!F18),IF('Advanced Entry'!F$5="Exponential",EXP('Advanced Entry'!F18),'Advanced Entry'!F18)))-'Advanced Entry'!F$6)/('Advanced Entry'!F$7-'Advanced Entry'!F$6),10*((IF('Advanced Entry'!F$5="Logarithm",LN(0.001+'Advanced Entry'!F18),IF('Advanced Entry'!F$5="Exponential",EXP('Advanced Entry'!F18),'Advanced Entry'!F18)))-'Advanced Entry'!F$6)/('Advanced Entry'!F$7-'Advanced Entry'!F$6)),1))),"No data")) | G18: =IF('Advanced Entry'!G18="","",IFERROR(MAX(0,MIN(10,ROUND(IF('Advanced Entry'!G$8="Decrease Risk",10-10*((IF('Advanced Entry'!G$5="Logarithm",LN(0.001+'Advanced Entry'!G18),IF('Advanced Entry'!G$5="Exponential",EXP('Advanced Entry'!G18),'Advanced Entry'!G18)))-'Advanced Entry'!G$6)/('Advanced Entry'!G$7-'Advanced Entry'!G$6),10*((IF('Advanced Entry'!G$5="Logarithm",LN(0.001+'Advanced Entry'!G18),IF('Advanced Entry'!G$5="Exponential",EXP('Advanced Entry'!G18),'Advanced Entry'!G18)))-'Advanced Entry'!G$6)/('Advanced Entry'!G$7-'Advanced Entry'!G$6)),1))),"No data")) | H18: =IF('Advanced Entry'!H18="","",IFERROR(MAX(0,MIN(10,ROUND(IF('Advanced Entry'!H$8="Decrease Risk",10-10*((IF('Advanced Entry'!H$5="Logarithm",LN(0.001+'Advanced Entry'!H18),IF('Advanced Entry'!H$5="Exponential",EXP('Advanced Entry'!H18),'Advanced Entry'!H18)))-'Advanced Entry'!H$6)/('Advanced Entry'!H$7-'Advanced Entry'!H$6),10*((IF('Advanced Entry'!H$5="Logarithm",LN(0.001+'Advanced Entry'!H18),IF('Advanced Entry'!H$5="Exponential",EXP('Advanced Entry'!H18),'Advanced Entry'!H18)))-'Advanced Entry'!H$6)/('Advanced Entry'!H$7-'Advanced Entry'!H$6)),1))),"No data")) | I18: =IF('Advanced Entry'!I18="","",IFERROR(MAX(0,MIN(10,ROUND(IF('Advanced Entry'!I$8="Decrease Risk",10-10*((IF('Advanced Entry'!I$5="Logarithm",LN(0.001+'Advanced Entry'!I18),IF('Advanced Entry'!I$5="Exponential",EXP('Advanced Entry'!I18),'Advanced Entry'!I18)))-'Advanced Entry'!I$6)/('Advanced Entry'!I$7-'Advanced Entry'!I$6),10*((IF('Advanced Entry'!I$5="Logarithm",LN(0.001+'Advanced Entry'!I18),IF('Advanced Entry'!I$5="Exponential",EXP('Advanced Entry'!I18),'Advanced Entry'!I18)))-'Advanced Entry'!I$6)/('Advanced Entry'!I$7-'Advanced Entry'!I$6)),1))),"No data")) | J18: =IF('Advanced Entry'!J18="","",IFERROR(MAX(0,MIN(10,ROUND(IF('Advanced Entry'!J$8="Decrease Risk",10-10*((IF('Advanced Entry'!J$5="Logarithm",LN(0.001+'Advanced Entry'!J18),IF('Advanced Entry'!J$5="Exponential",EXP('Advanced Entry'!J18),'Advanced Entry'!J18)))-'Advanced Entry'!J$6)/('Advanced Entry'!J$7-'Advanced Entry'!J$6),10*((IF('Advanced Entry'!J$5="Logarithm",LN(0.001+'Advanced Entry'!J18),IF('Advanced Entry'!J$5="Exponential",EXP('Advanced Entry'!J18),'Advanced Entry'!J18)))-'Advanced Entry'!J$6)/('Advanced Entry'!J$7-'Advanced Entry'!J$6)),1))),"No data")) | K18: =IF('Advanced Entry'!K18="","",IFERROR(MAX(0,MIN(10,ROUND(IF('Advanced Entry'!K$8="Decrease Risk",10-10*((IF('Advanced Entry'!K$5="Logarithm",LN(0.001+'Advanced Entry'!K18),IF('Advanced Entry'!K$5="Exponential",EXP('Advanced Entry'!K18),'Advanced Entry'!K18)))-'Advanced Entry'!K$6)/('Advanced Entry'!K$7-'Advanced Entry'!K$6),10*((IF('Advanced Entry'!K$5="Logarithm",LN(0.001+'Advanced Entry'!K18),IF('Advanced Entry'!K$5="Exponential",EXP('Advanced Entry'!K18),'Advanced Entry'!K18)))-'Advanced Entry'!K$6)/('Advanced Entry'!K$7-'Advanced Entry'!K$6)),1))),"No data")) | ... AB18: =IF('Advanced Entry'!AB18="","",IFERROR(MAX(0,MIN(10,ROUND(IF('Advanced Entry'!AB$8="Decrease Risk",10-10*((IF('Advanced Entry'!AB$5="Logarithm",LN(0.001+'Advanced Entry'!AB18),IF('Advanced Entry'!AB$5="Exponential",EXP('Advanced Entry'!AB18),'Advanced Entry'!AB18)))-'Advanced Entry'!AB$6)/('Advanced Entry'!AB$7-'Advanced Entry'!AB$6),10*((IF('Advanced Entry'!AB$5="Logarithm",LN(0.001+'Advanced Entry'!AB18),IF('Advanced Entry'!AB$5="Exponential",EXP('Advanced Entry'!AB18),'Advanced Entry'!AB18)))-'Advanced Entry'!AB$6)/('Advanced Entry'!AB$7-'Advanced Entry'!AB$6)),1))),"No data"))
A19: Dar es Salaam | B19: Kigamboni Municipal | C19: C055 | D19: =IF('Advanced Entry'!D19="","",IFERROR(MAX(0,MIN(10,ROUND(IF('Advanced Entry'!D$8="Decrease Risk",10-10*((IF('Advanced Entry'!D$5="Logarithm",LN(0.001+'Advanced Entry'!D19),IF('Advanced Entry'!D$5="Exponential",EXP('Advanced Entry'!D19),'Advanced Entry'!D19)))-'Advanced Entry'!D$6)/('Advanced Entry'!D$7-'Advanced Entry'!D$6),10*((IF('Advanced Entry'!D$5="Logarithm",LN(0.001+'Advanced Entry'!D19),IF('Advanced Entry'!D$5="Exponential",EXP('Advanced Entry'!D19),'Advanced Entry'!D19)))-'Advanced Entry'!D$6)/('Advanced Entry'!D$7-'Advanced Entry'!D$6)),1))),"No data")) | E19: =IF('Advanced Entry'!E19="","",IFERROR(MAX(0,MIN(10,ROUND(IF('Advanced Entry'!E$8="Decrease Risk",10-10*((IF('Advanced Entry'!E$5="Logarithm",LN(0.001+'Advanced Entry'!E19),IF('Advanced Entry'!E$5="Exponential",EXP('Advanced Entry'!E19),'Advanced Entry'!E19)))-'Advanced Entry'!E$6)/('Advanced Entry'!E$7-'Advanced Entry'!E$6),10*((IF('Advanced Entry'!E$5="Logarithm",LN(0.001+'Advanced Entry'!E19),IF('Advanced Entry'!E$5="Exponential",EXP('Advanced Entry'!E19),'Advanced Entry'!E19)))-'Advanced Entry'!E$6)/('Advanced Entry'!E$7-'Advanced Entry'!E$6)),1))),"No data")) | F19: =IF('Advanced Entry'!F19="","",IFERROR(MAX(0,MIN(10,ROUND(IF('Advanced Entry'!F$8="Decrease Risk",10-10*((IF('Advanced Entry'!F$5="Logarithm",LN(0.001+'Advanced Entry'!F19),IF('Advanced Entry'!F$5="Exponential",EXP('Advanced Entry'!F19),'Advanced Entry'!F19)))-'Advanced Entry'!F$6)/('Advanced Entry'!F$7-'Advanced Entry'!F$6),10*((IF('Advanced Entry'!F$5="Logarithm",LN(0.001+'Advanced Entry'!F19),IF('Advanced Entry'!F$5="Exponential",EXP('Advanced Entry'!F19),'Advanced Entry'!F19)))-'Advanced Entry'!F$6)/('Advanced Entry'!F$7-'Advanced Entry'!F$6)),1))),"No data")) | G19: =IF('Advanced Entry'!G19="","",IFERROR(MAX(0,MIN(10,ROUND(IF('Advanced Entry'!G$8="Decrease Risk",10-10*((IF('Advanced Entry'!G$5="Logarithm",LN(0.001+'Advanced Entry'!G19),IF('Advanced Entry'!G$5="Exponential",EXP('Advanced Entry'!G19),'Advanced Entry'!G19)))-'Advanced Entry'!G$6)/('Advanced Entry'!G$7-'Advanced Entry'!G$6),10*((IF('Advanced Entry'!G$5="Logarithm",LN(0.001+'Advanced Entry'!G19),IF('Advanced Entry'!G$5="Exponential",EXP('Advanced Entry'!G19),'Advanced Entry'!G19)))-'Advanced Entry'!G$6)/('Advanced Entry'!G$7-'Advanced Entry'!G$6)),1))),"No data")) | H19: =IF('Advanced Entry'!H19="","",IFERROR(MAX(0,MIN(10,ROUND(IF('Advanced Entry'!H$8="Decrease Risk",10-10*((IF('Advanced Entry'!H$5="Logarithm",LN(0.001+'Advanced Entry'!H19),IF('Advanced Entry'!H$5="Exponential",EXP('Advanced Entry'!H19),'Advanced Entry'!H19)))-'Advanced Entry'!H$6)/('Advanced Entry'!H$7-'Advanced Entry'!H$6),10*((IF('Advanced Entry'!H$5="Logarithm",LN(0.001+'Advanced Entry'!H19),IF('Advanced Entry'!H$5="Exponential",EXP('Advanced Entry'!H19),'Advanced Entry'!H19)))-'Advanced Entry'!H$6)/('Advanced Entry'!H$7-'Advanced Entry'!H$6)),1))),"No data")) | I19: =IF('Advanced Entry'!I19="","",IFERROR(MAX(0,MIN(10,ROUND(IF('Advanced Entry'!I$8="Decrease Risk",10-10*((IF('Advanced Entry'!I$5="Logarithm",LN(0.001+'Advanced Entry'!I19),IF('Advanced Entry'!I$5="Exponential",EXP('Advanced Entry'!I19),'Advanced Entry'!I19)))-'Advanced Entry'!I$6)/('Advanced Entry'!I$7-'Advanced Entry'!I$6),10*((IF('Advanced Entry'!I$5="Logarithm",LN(0.001+'Advanced Entry'!I19),IF('Advanced Entry'!I$5="Exponential",EXP('Advanced Entry'!I19),'Advanced Entry'!I19)))-'Advanced Entry'!I$6)/('Advanced Entry'!I$7-'Advanced Entry'!I$6)),1))),"No data")) | J19: =IF('Advanced Entry'!J19="","",IFERROR(MAX(0,MIN(10,ROUND(IF('Advanced Entry'!J$8="Decrease Risk",10-10*((IF('Advanced Entry'!J$5="Logarithm",LN(0.001+'Advanced Entry'!J19),IF('Advanced Entry'!J$5="Exponential",EXP('Advanced Entry'!J19),'Advanced Entry'!J19)))-'Advanced Entry'!J$6)/('Advanced Entry'!J$7-'Advanced Entry'!J$6),10*((IF('Advanced Entry'!J$5="Logarithm",LN(0.001+'Advanced Entry'!J19),IF('Advanced Entry'!J$5="Exponential",EXP('Advanced Entry'!J19),'Advanced Entry'!J19)))-'Advanced Entry'!J$6)/('Advanced Entry'!J$7-'Advanced Entry'!J$6)),1))),"No data")) | K19: =IF('Advanced Entry'!K19="","",IFERROR(MAX(0,MIN(10,ROUND(IF('Advanced Entry'!K$8="Decrease Risk",10-10*((IF('Advanced Entry'!K$5="Logarithm",LN(0.001+'Advanced Entry'!K19),IF('Advanced Entry'!K$5="Exponential",EXP('Advanced Entry'!K19),'Advanced Entry'!K19)))-'Advanced Entry'!K$6)/('Advanced Entry'!K$7-'Advanced Entry'!K$6),10*((IF('Advanced Entry'!K$5="Logarithm",LN(0.001+'Advanced Entry'!K19),IF('Advanced Entry'!K$5="Exponential",EXP('Advanced Entry'!K19),'Advanced Entry'!K19)))-'Advanced Entry'!K$6)/('Advanced Entry'!K$7-'Advanced Entry'!K$6)),1))),"No data")) | ... AB19: =IF('Advanced Entry'!AB19="","",IFERROR(MAX(0,MIN(10,ROUND(IF('Advanced Entry'!AB$8="Decrease Risk",10-10*((IF('Advanced Entry'!AB$5="Logarithm",LN(0.001+'Advanced Entry'!AB19),IF('Advanced Entry'!AB$5="Exponential",EXP('Advanced Entry'!AB19),'Advanced Entry'!AB19)))-'Advanced Entry'!AB$6)/('Advanced Entry'!AB$7-'Advanced Entry'!AB$6),10*((IF('Advanced Entry'!AB$5="Logarithm",LN(0.001+'Advanced Entry'!AB19),IF('Advanced Entry'!AB$5="Exponential",EXP('Advanced Entry'!AB19),'Advanced Entry'!AB19)))-'Advanced Entry'!AB$6)/('Advanced Entry'!AB$7-'Advanced Entry'!AB$6)),1))),"No data"))
A20: Dar es Salaam | B20: Kinondoni Municipal | C20: C052 | D20: =IF('Advanced Entry'!D20="","",IFERROR(MAX(0,MIN(10,ROUND(IF('Advanced Entry'!D$8="Decrease Risk",10-10*((IF('Advanced Entry'!D$5="Logarithm",LN(0.001+'Advanced Entry'!D20),IF('Advanced Entry'!D$5="Exponential",EXP('Advanced Entry'!D20),'Advanced Entry'!D20)))-'Advanced Entry'!D$6)/('Advanced Entry'!D$7-'Advanced Entry'!D$6),10*((IF('Advanced Entry'!D$5="Logarithm",LN(0.001+'Advanced Entry'!D20),IF('Advanced Entry'!D$5="Exponential",EXP('Advanced Entry'!D20),'Advanced Entry'!D20)))-'Advanced Entry'!D$6)/('Advanced Entry'!D$7-'Advanced Entry'!D$6)),1))),"No data")) | E20: =IF('Advanced Entry'!E20="","",IFERROR(MAX(0,MIN(10,ROUND(IF('Advanced Entry'!E$8="Decrease Risk",10-10*((IF('Advanced Entry'!E$5="Logarithm",LN(0.001+'Advanced Entry'!E20),IF('Advanced Entry'!E$5="Exponential",EXP('Advanced Entry'!E20),'Advanced Entry'!E20)))-'Advanced Entry'!E$6)/('Advanced Entry'!E$7-'Advanced Entry'!E$6),10*((IF('Advanced Entry'!E$5="Logarithm",LN(0.001+'Advanced Entry'!E20),IF('Advanced Entry'!E$5="Exponential",EXP('Advanced Entry'!E20),'Advanced Entry'!E20)))-'Advanced Entry'!E$6)/('Advanced Entry'!E$7-'Advanced Entry'!E$6)),1))),"No data")) | F20: =IF('Advanced Entry'!F20="","",IFERROR(MAX(0,MIN(10,ROUND(IF('Advanced Entry'!F$8="Decrease Risk",10-10*((IF('Advanced Entry'!F$5="Logarithm",LN(0.001+'Advanced Entry'!F20),IF('Advanced Entry'!F$5="Exponential",EXP('Advanced Entry'!F20),'Advanced Entry'!F20)))-'Advanced Entry'!F$6)/('Advanced Entry'!F$7-'Advanced Entry'!F$6),10*((IF('Advanced Entry'!F$5="Logarithm",LN(0.001+'Advanced Entry'!F20),IF('Advanced Entry'!F$5="Exponential",EXP('Advanced Entry'!F20),'Advanced Entry'!F20)))-'Advanced Entry'!F$6)/('Advanced Entry'!F$7-'Advanced Entry'!F$6)),1))),"No data")) | G20: =IF('Advanced Entry'!G20="","",IFERROR(MAX(0,MIN(10,ROUND(IF('Advanced Entry'!G$8="Decrease Risk",10-10*((IF('Advanced Entry'!G$5="Logarithm",LN(0.001+'Advanced Entry'!G20),IF('Advanced Entry'!G$5="Exponential",EXP('Advanced Entry'!G20),'Advanced Entry'!G20)))-'Advanced Entry'!G$6)/('Advanced Entry'!G$7-'Advanced Entry'!G$6),10*((IF('Advanced Entry'!G$5="Logarithm",LN(0.001+'Advanced Entry'!G20),IF('Advanced Entry'!G$5="Exponential",EXP('Advanced Entry'!G20),'Advanced Entry'!G20)))-'Advanced Entry'!G$6)/('Advanced Entry'!G$7-'Advanced Entry'!G$6)),1))),"No data")) | H20: =IF('Advanced Entry'!H20="","",IFERROR(MAX(0,MIN(10,ROUND(IF('Advanced Entry'!H$8="Decrease Risk",10-10*((IF('Advanced Entry'!H$5="Logarithm",LN(0.001+'Advanced Entry'!H20),IF('Advanced Entry'!H$5="Exponential",EXP('Advanced Entry'!H20),'Advanced Entry'!H20)))-'Advanced Entry'!H$6)/('Advanced Entry'!H$7-'Advanced Entry'!H$6),10*((IF('Advanced Entry'!H$5="Logarithm",LN(0.001+'Advanced Entry'!H20),IF('Advanced Entry'!H$5="Exponential",EXP('Advanced Entry'!H20),'Advanced Entry'!H20)))-'Advanced Entry'!H$6)/('Advanced Entry'!H$7-'Advanced Entry'!H$6)),1))),"No data")) | I20: =IF('Advanced Entry'!I20="","",IFERROR(MAX(0,MIN(10,ROUND(IF('Advanced Entry'!I$8="Decrease Risk",10-10*((IF('Advanced Entry'!I$5="Logarithm",LN(0.001+'Advanced Entry'!I20),IF('Advanced Entry'!I$5="Exponential",EXP('Advanced Entry'!I20),'Advanced Entry'!I20)))-'Advanced Entry'!I$6)/('Advanced Entry'!I$7-'Advanced Entry'!I$6),10*((IF('Advanced Entry'!I$5="Logarithm",LN(0.001+'Advanced Entry'!I20),IF('Advanced Entry'!I$5="Exponential",EXP('Advanced Entry'!I20),'Advanced Entry'!I20)))-'Advanced Entry'!I$6)/('Advanced Entry'!I$7-'Advanced Entry'!I$6)),1))),"No data")) | J20: =IF('Advanced Entry'!J20="","",IFERROR(MAX(0,MIN(10,ROUND(IF('Advanced Entry'!J$8="Decrease Risk",10-10*((IF('Advanced Entry'!J$5="Logarithm",LN(0.001+'Advanced Entry'!J20),IF('Advanced Entry'!J$5="Exponential",EXP('Advanced Entry'!J20),'Advanced Entry'!J20)))-'Advanced Entry'!J$6)/('Advanced Entry'!J$7-'Advanced Entry'!J$6),10*((IF('Advanced Entry'!J$5="Logarithm",LN(0.001+'Advanced Entry'!J20),IF('Advanced Entry'!J$5="Exponential",EXP('Advanced Entry'!J20),'Advanced Entry'!J20)))-'Advanced Entry'!J$6)/('Advanced Entry'!J$7-'Advanced Entry'!J$6)),1))),"No data")) | K20: =IF('Advanced Entry'!K20="","",IFERROR(MAX(0,MIN(10,ROUND(IF('Advanced Entry'!K$8="Decrease Risk",10-10*((IF('Advanced Entry'!K$5="Logarithm",LN(0.001+'Advanced Entry'!K20),IF('Advanced Entry'!K$5="Exponential",EXP('Advanced Entry'!K20),'Advanced Entry'!K20)))-'Advanced Entry'!K$6)/('Advanced Entry'!K$7-'Advanced Entry'!K$6),10*((IF('Advanced Entry'!K$5="Logarithm",LN(0.001+'Advanced Entry'!K20),IF('Advanced Entry'!K$5="Exponential",EXP('Advanced Entry'!K20),'Advanced Entry'!K20)))-'Advanced Entry'!K$6)/('Advanced Entry'!K$7-'Advanced Entry'!K$6)),1))),"No data")) | ... AB20: =IF('Advanced Entry'!AB20="","",IFERROR(MAX(0,MIN(10,ROUND(IF('Advanced Entry'!AB$8="Decrease Risk",10-10*((IF('Advanced Entry'!AB$5="Logarithm",LN(0.001+'Advanced Entry'!AB20),IF('Advanced Entry'!AB$5="Exponential",EXP('Advanced Entry'!AB20),'Advanced Entry'!AB20)))-'Advanced Entry'!AB$6)/('Advanced Entry'!AB$7-'Advanced Entry'!AB$6),10*((IF('Advanced Entry'!AB$5="Logarithm",LN(0.001+'Advanced Entry'!AB20),IF('Advanced Entry'!AB$5="Exponential",EXP('Advanced Entry'!AB20),'Advanced Entry'!AB20)))-'Advanced Entry'!AB$6)/('Advanced Entry'!AB$7-'Advanced Entry'!AB$6)),1))),"No data"))
